<?xml version="1.0" ?>
<!-- =================================================================================== -->
<!-- |    This document was autogenerated by xacro from p_hand.urdf.xacro              | -->
<!-- |    EDITING THIS FILE BY HAND IS NOT RECOMMENDED                                 | -->
<!-- =================================================================================== -->
<robot name="p_hand" xmlns:xacro="http://www.ros.org/wiki/xacro">
  <!-- 
=================
DEFINITIONS
=================
 -->
  <!-- 
=================
ROBOT DESCRIPTION
=================
 -->
  <!-- LINKS -->
  <!-- Base and swivels -->
  <link name="base_link">
    <visual>
      <geometry>
        <mesh filename="package://p_hand_description/meshes/base_link.STL"/>
      </geometry>
      <origin rpy="0 0 0" xyz="-0.0115 0 -0.127"/>
      <material name="blue">
        <color rgba="0 0 .8 1"/>
      </material>
    </visual>
    <collision>
      <geometry>
        <mesh filename="package://p_hand_description/meshes/base_link.STL"/>
      </geometry>
      <origin rpy="0 0 0" xyz="-0.0115 0 -0.127"/>
    </collision>
    <inertial>
      <origin rpy="0 0 0" xyz="0.050416 0.000105 0.080742"/>
      <mass value="0.1"/>
      <!-- TODO -->
      <inertia ixx="0.4" ixy="0.0" ixz="0.0" iyy="0.4" iyz="0.0" izz="0.2"/>
    </inertial>
  </link>
  <link name="swivel1">
    <visual>
      <geometry>
        <mesh filename="package://p_hand_description/meshes/swivel1.STL"/>
      </geometry>
      <origin rpy="0 0 0" xyz="0 0 -0.045"/>
      <material name="blue">
        <color rgba="0 0 .8 1"/>
      </material>
    </visual>
    <collision>
      <geometry>
        <mesh filename="package://p_hand_description/meshes/swivel1.STL"/>
      </geometry>
      <origin rpy="0 0 0" xyz="0 0 -0.045"/>
    </collision>
  </link>
  <link name="swivel2">
    <visual>
      <geometry>
        <mesh filename="package://p_hand_description/meshes/swivel2.STL"/>
      </geometry>
      <origin rpy="0 0 0" xyz="0 0 -0.140"/>
      <material name="blue">
        <color rgba="0 0 .8 1"/>
      </material>
    </visual>
    <collision>
      <geometry>
        <mesh filename="package://p_hand_description/meshes/swivel2.STL"/>
      </geometry>
      <origin rpy="0 0 0" xyz="0 0 -0.140"/>
    </collision>
  </link>
  <link name="lower0">
    <visual>
      <geometry>
        <mesh filename="package://p_hand_description/meshes/lower.STL"/>
      </geometry>
      <origin rpy="0 0 0" xyz="0 0 -0.025"/>
      <material name="white">
        <color rgba="1 1 1 1"/>
      </material>
    </visual>
    <collision>
      <geometry>
        <mesh filename="package://p_hand_description/meshes/lower.STL"/>
      </geometry>
      <origin rpy="0 0 0" xyz="0 0 -0.025"/>
    </collision>
  </link>
  <link name="lower1">
    <visual>
      <geometry>
        <mesh filename="package://p_hand_description/meshes/lower.STL"/>
      </geometry>
      <origin rpy="0 0 0" xyz="0 0 -0.025"/>
      <material name="white">
        <color rgba="1 1 1 1"/>
      </material>
    </visual>
    <collision>
      <geometry>
        <mesh filename="package://p_hand_description/meshes/lower.STL"/>
      </geometry>
      <origin rpy="0 0 0" xyz="0 0 -0.025"/>
    </collision>
  </link>
  <link name="lower2">
    <visual>
      <geometry>
        <mesh filename="package://p_hand_description/meshes/lower.STL"/>
      </geometry>
      <origin rpy="0 0 0" xyz="0 0 -0.025"/>
      <material name="white">
        <color rgba="1 1 1 1"/>
      </material>
    </visual>
    <collision>
      <geometry>
        <mesh filename="package://p_hand_description/meshes/lower.STL"/>
      </geometry>
      <origin rpy="0 0 0" xyz="0 0 -0.025"/>
    </collision>
  </link>
  <link name="upper0">
    <visual>
      <geometry>
        <mesh filename="package://p_hand_description/meshes/upper.STL"/>
      </geometry>
      <origin rpy="0 0 0" xyz="0 0 -0.025"/>
      <material name="blue">
        <color rgba="0 0 .8 1"/>
      </material>
    </visual>
    <collision>
      <geometry>
        <mesh filename="package://p_hand_description/meshes/upper.STL"/>
      </geometry>
      <origin rpy="0 0 0" xyz="0 0 -0.025"/>
    </collision>
  </link>
  <link name="upper1">
    <visual>
      <geometry>
        <mesh filename="package://p_hand_description/meshes/upper.STL"/>
      </geometry>
      <origin rpy="0 0 0" xyz="0 0 -0.025"/>
      <material name="blue">
        <color rgba="0 0 .8 1"/>
      </material>
    </visual>
    <collision>
      <geometry>
        <mesh filename="package://p_hand_description/meshes/upper.STL"/>
      </geometry>
      <origin rpy="0 0 0" xyz="0 0 -0.025"/>
    </collision>
  </link>
  <link name="upper2">
    <visual>
      <geometry>
        <mesh filename="package://p_hand_description/meshes/upper.STL"/>
      </geometry>
      <origin rpy="0 0 0" xyz="0 0 -0.025"/>
      <material name="blue">
        <color rgba="0 0 .8 1"/>
      </material>
    </visual>
    <collision>
      <geometry>
        <mesh filename="package://p_hand_description/meshes/upper.STL"/>
      </geometry>
      <origin rpy="0 0 0" xyz="0 0 -0.025"/>
    </collision>
  </link>
  <!-- Tips -->
  <link name="tip0"/>
  <link name="tip1"/>
  <link name="tip2"/>
  <!-- JOINTS -->
  <!-- Base and swivels -->
  <joint name="base_link_swivel1" type="revolute">
    <parent link="base_link"/>
    <child link="swivel1"/>
    <limit effort="1000.0" lower="1.047198" upper="4.188792" velocity="0.5"/>
    <origin rpy="0 0 0" xyz="0 0 0"/>
    <axis xyz="0 0 1"/>
  </joint>
  <joint name="base_link_swivel2" type="revolute">
    <parent link="base_link"/>
    <child link="swivel2"/>
    <limit effort="1000.0" lower="2.094396" upper="5.23599" velocity="0.5"/>
    <origin rpy="0 0 0" xyz="0 0 0"/>
    <axis xyz="0 0 1"/>
  </joint>
  <joint name="base_link_lower0" type="revolute">
    <parent link="base_link"/>
    <child link="lower0"/>
    <limit effort="1000.0" lower="-1.570797" upper="0.872665" velocity="0.5"/>
    <origin rpy="1.5708  0 0" xyz="0.06 0 0.045"/>
    <axis xyz="0 0 1"/>
  </joint>
  <joint name="swivel1_lower1" type="revolute">
    <parent link="swivel1"/>
    <child link="lower1"/>
    <limit effort="1000.0" lower="-1.570797" upper="0.872665" velocity="0.5"/>
    <origin rpy="1.5708  0 0" xyz="0.06 0 0.045"/>
    <axis xyz="0 0 1"/>
  </joint>
  <joint name="swivel2_lower2" type="revolute">
    <parent link="swivel2"/>
    <child link="lower2"/>
    <limit effort="1000.0" lower="-1.570797" upper="0.872665" velocity="0.5"/>
    <origin rpy="1.5708  0 0" xyz="0.06 0 0.045"/>
    <axis xyz="0 0 1"/>
  </joint>
  <joint name="lower0_upper0" type="revolute">
    <parent link="lower0"/>
    <child link="upper0"/>
    <limit effort="1000.0" lower="-1.570797" upper="1.74533" velocity="0.5"/>
    <origin rpy="0  0 0" xyz="0 0.065 0"/>
    <axis xyz="0 0 1"/>
  </joint>
  <joint name="lower1_upper1" type="revolute">
    <parent link="lower1"/>
    <child link="upper1"/>
    <limit effort="1000.0" lower="-1.570797" upper="1.74533" velocity="0.5"/>
    <origin rpy="0  0 0" xyz="0 0.065 0"/>
    <axis xyz="0 0 1"/>
  </joint>
  <joint name="lower2_upper2" type="revolute">
    <parent link="lower2"/>
    <child link="upper2"/>
    <limit effort="1000.0" lower="-1.570797" upper="1.74533" velocity="0.5"/>
    <origin rpy="0  0 0" xyz="0 0.065 0"/>
    <axis xyz="0 0 1"/>
  </joint>
  <joint name="upper0_tip0" type="fixed">
    <parent link="upper0"/>
    <child link="tip0"/>
    <origin rpy="0  0 0" xyz="-0.007 0.062 0"/>
  </joint>
  <joint name="upper1_tip1" type="fixed">
    <parent link="upper1"/>
    <child link="tip1"/>
    <origin rpy="0  0 0" xyz="-0.007 0.062 0"/>
  </joint>
  <joint name="upper2_tip2" type="fixed">
    <parent link="upper2"/>
    <child link="tip2"/>
    <origin rpy="0  0 0" xyz="-0.007 0.062 0"/>
  </joint>
</robot>

