<?xml version="1.0" ?>
<!-- =================================================================================== -->
<!-- |    This document was autogenerated by xacro from p_care.urdf.xacro              | -->
<!-- |    EDITING THIS FILE BY HAND IS NOT RECOMMENDED                                 | -->
<!-- =================================================================================== -->
<robot name="p_care" xmlns:xacro="http://www.ros.org/wiki/xacro">
  <material name="blue">
    <color rgba="0.12549019607843137 0.2784313725490196 0.43529411764705883 1"/>
  </material>
  <material name="black">
    <color rgba="0 0 0 1"/>
  </material>
  <material name="white">
    <color rgba="1 1 1 1"/>
  </material>
  <link name="base_footprint">

  </link>
  <joint name="base_joint" type="fixed">
    <origin rpy="0 0 0" xyz="-0.113 0 0"/>
    <parent link="base_footprint"/>
    <child link="platform_base_link"/>
  </joint>
  <link name="platform_base_link">
    <visual>
      <geometry>
        <mesh filename="package://platform_description/meshes/platform_LIO.STL"/>
      </geometry>
      <origin rpy="0 0 1.57" xyz="0 0 -0.07"/>
      <material name="white"/>
    </visual>
  </link>
  <joint name="lidar_front_joint" type="fixed">
    <parent link="base_footprint"/>
    <child link="lidar_front"/>
    <origin rpy="0 3.14 0" xyz="0.08202 0.0 -0.01"/>
  </joint>
  <link name="lidar_front">
    <collision>
      <origin rpy="0 0 0" xyz="0 0 0"/>
      <geometry>
        <box size="0.0130 0.0567 0.0118"/>
      </geometry>
    </collision>
    <!-- This inertial field doesn't contain reliable data!! -->
    <inertial>
      <mass value="0.564"/>
      <origin xyz="0 0 0"/>
      <inertia ixx="0.003881243" ixy="0.0" ixz="0.0" iyy="0.000498940" iyz="0.0" izz="0.003879257"/>
    </inertial>
  </link>
  <joint name="lidar_back_joint" type="fixed">
    <parent link="base_footprint"/>
    <child link="lidar_back"/>
    <origin rpy="0 3.14 0" xyz="-0.432 0.0 -0.01"/>
  </joint>
  <link name="lidar_back">
    <collision>
      <origin rpy="0 0 0" xyz="0 0 0"/>
      <geometry>
        <box size="0.0130 0.0567 0.0118"/>
      </geometry>
    </collision>
    <!-- This inertial field doesn't contain reliable data!! -->
    <inertial>
      <mass value="0.564"/>
      <origin xyz="0 0 0"/>
      <inertia ixx="0.003881243" ixy="0.0" ixz="0.0" iyy="0.000498940" iyz="0.0" izz="0.003879257"/>
    </inertial>
  </link>
  <joint name="ultrasonic_sensor_1_joint" type="fixed">
    <parent link="base_footprint"/>
    <child link="US1"/>
    <origin rpy="0 0 3.14" xyz="-0.625 -0.095 0.053"/>
  </joint>
  <link name="US1">
    <collision>
      <origin rpy="0 0 0" xyz="0 0 0"/>
      <geometry>
        <box size="0.0130 0.0567 0.0118"/>
      </geometry>
    </collision>
    <!-- This inertial field doesn't contain reliable data!! -->
    <inertial>
      <mass value="0.564"/>
      <origin xyz="0 0 0"/>
      <inertia ixx="0.003881243" ixy="0.0" ixz="0.0" iyy="0.000498940" iyz="0.0" izz="0.003879257"/>
    </inertial>
  </link>
  <joint name="ultrasonic_sensor_2_joint" type="fixed">
    <parent link="base_footprint"/>
    <child link="US2"/>
    <origin rpy="0 0 -2.355" xyz="-0.585 -0.231 0.053"/>
  </joint>
  <link name="US2">
    <collision>
      <origin rpy="0 0 0" xyz="0 0 0"/>
      <geometry>
        <box size="0.0130 0.0567 0.0118"/>
      </geometry>
    </collision>
    <!-- This inertial field doesn't contain reliable data!! -->
    <inertial>
      <mass value="0.564"/>
      <origin xyz="0 0 0"/>
      <inertia ixx="0.003881243" ixy="0.0" ixz="0.0" iyy="0.000498940" iyz="0.0" izz="0.003879257"/>
    </inertial>
  </link>
  <joint name="ultrasonic_sensor_3_joint" type="fixed">
    <parent link="base_footprint"/>
    <child link="US3"/>
    <origin rpy="0 0 -1.57" xyz="-0.272 -0.255 0.053"/>
  </joint>
  <link name="US3">
    <collision>
      <origin rpy="0 0 0" xyz="0 0 0"/>
      <geometry>
        <box size="0.0130 0.0567 0.0118"/>
      </geometry>
    </collision>
    <!-- This inertial field doesn't contain reliable data!! -->
    <inertial>
      <mass value="0.564"/>
      <origin xyz="0 0 0"/>
      <inertia ixx="0.003881243" ixy="0.0" ixz="0.0" iyy="0.000498940" iyz="0.0" izz="0.003879257"/>
    </inertial>
  </link>
  <joint name="ultrasonic_sensor_4_joint" type="fixed">
    <parent link="base_footprint"/>
    <child link="US4"/>
    <origin rpy="0 0 -0.785" xyz="0.097 -0.255 0.053"/>
  </joint>
  <link name="US4">
    <collision>
      <origin rpy="0 0 0" xyz="0 0 0"/>
      <geometry>
        <box size="0.0130 0.0567 0.0118"/>
      </geometry>
    </collision>
    <!-- This inertial field doesn't contain reliable data!! -->
    <inertial>
      <mass value="0.564"/>
      <origin xyz="0 0 0"/>
      <inertia ixx="0.003881243" ixy="0.0" ixz="0.0" iyy="0.000498940" iyz="0.0" izz="0.003879257"/>
    </inertial>
  </link>
  <joint name="ultrasonic_sensor_5_joint" type="fixed">
    <parent link="base_footprint"/>
    <child link="US5"/>
    <origin rpy="0 0 -0.07" xyz="0.145 -0.121 0.053"/>
  </joint>
  <link name="US5">
    <collision>
      <origin rpy="0 0 0" xyz="0 0 0"/>
      <geometry>
        <box size="0.0130 0.0567 0.0118"/>
      </geometry>
    </collision>
    <!-- This inertial field doesn't contain reliable data!! -->
    <inertial>
      <mass value="0.564"/>
      <origin xyz="0 0 0"/>
      <inertia ixx="0.003881243" ixy="0.0" ixz="0.0" iyy="0.000498940" iyz="0.0" izz="0.003879257"/>
    </inertial>
  </link>
  <joint name="ultrasonic_sensor_6_joint" type="fixed">
    <parent link="base_footprint"/>
    <child link="US6"/>
    <origin rpy="0 0 0.07" xyz="0.145 0.121 0.053"/>
  </joint>
  <link name="US6">
    <collision>
      <origin rpy="0 0 0" xyz="0 0 0"/>
      <geometry>
        <box size="0.0130 0.0567 0.0118"/>
      </geometry>
    </collision>
    <!-- This inertial field doesn't contain reliable data!! -->
    <inertial>
      <mass value="0.564"/>
      <origin xyz="0 0 0"/>
      <inertia ixx="0.003881243" ixy="0.0" ixz="0.0" iyy="0.000498940" iyz="0.0" izz="0.003879257"/>
    </inertial>
  </link>
  <joint name="ultrasonic_sensor_7_joint" type="fixed">
    <parent link="base_footprint"/>
    <child link="US7"/>
    <origin rpy="0 0 0.785" xyz="0.097 0.255 0.053"/>
  </joint>
  <link name="US7">
    <collision>
      <origin rpy="0 0 0" xyz="0 0 0"/>
      <geometry>
        <box size="0.0130 0.0567 0.0118"/>
      </geometry>
    </collision>
    <!-- This inertial field doesn't contain reliable data!! -->
    <inertial>
      <mass value="0.564"/>
      <origin xyz="0 0 0"/>
      <inertia ixx="0.003881243" ixy="0.0" ixz="0.0" iyy="0.000498940" iyz="0.0" izz="0.003879257"/>
    </inertial>
  </link>
  <joint name="ultrasonic_sensor_8_joint" type="fixed">
    <parent link="base_footprint"/>
    <child link="US8"/>
    <origin rpy="0 0 1.57" xyz="-0.272 0.255 0.053"/>
  </joint>
  <link name="US8">
    <collision>
      <origin rpy="0 0 0" xyz="0 0 0"/>
      <geometry>
        <box size="0.0130 0.0567 0.0118"/>
      </geometry>
    </collision>
    <!-- This inertial field doesn't contain reliable data!! -->
    <inertial>
      <mass value="0.564"/>
      <origin xyz="0 0 0"/>
      <inertia ixx="0.003881243" ixy="0.0" ixz="0.0" iyy="0.000498940" iyz="0.0" izz="0.003879257"/>
    </inertial>
  </link>
  <joint name="ultrasonic_sensor_9_joint" type="fixed">
    <parent link="base_footprint"/>
    <child link="US9"/>
    <origin rpy="0 0 2.355" xyz="-0.585 0.231 0.053"/>
  </joint>
  <link name="US9">
    <collision>
      <origin rpy="0 0 0" xyz="0 0 0"/>
      <geometry>
        <box size="0.0130 0.0567 0.0118"/>
      </geometry>
    </collision>
    <!-- This inertial field doesn't contain reliable data!! -->
    <inertial>
      <mass value="0.564"/>
      <origin xyz="0 0 0"/>
      <inertia ixx="0.003881243" ixy="0.0" ixz="0.0" iyy="0.000498940" iyz="0.0" izz="0.003879257"/>
    </inertial>
  </link>
  <joint name="ultrasonic_sensor_10_joint" type="fixed">
    <parent link="base_footprint"/>
    <child link="US10"/>
    <origin rpy="0 0 3.14" xyz="-0.625 0.095 0.053"/>
  </joint>
  <link name="US10">
    <collision>
      <origin rpy="0 0 0" xyz="0 0 0"/>
      <geometry>
        <box size="0.0130 0.0567 0.0118"/>
      </geometry>
    </collision>
    <!-- This inertial field doesn't contain reliable data!! -->
    <inertial>
      <mass value="0.564"/>
      <origin xyz="0 0 0"/>
      <inertia ixx="0.003881243" ixy="0.0" ixz="0.0" iyy="0.000498940" iyz="0.0" izz="0.003879257"/>
    </inertial>
  </link>
  <joint name="LIOc_robot_base_link_joint" type="fixed">
    <origin rpy="0 0 0" xyz="0 0 -0.0725"/>
    <child link="LIOc_base_link"/>
    <parent link="platform_base_link"/>
  </joint>
  <link name="LIOc_base_link">
    <inertial>
      <origin rpy="0 0 0" xyz="-0.000129164615674658 -0.0650850183395308 0.216920107164484"/>
      <mass value="42.2499541196203"/>
      <inertia ixx="2.19278239601341" ixy="-0.00608161487223685" ixz="-0.000366786945712441" iyy="2.04392192430378" iyz="-0.137313138030081" izz="1.93900754024424"/>
    </inertial>
    <visual>
      <geometry>
        <mesh filename="package://p_care_description/meshes/base_link.STL"/>
      </geometry>
      <material name="white"/>
    </visual>
    <collision>
      <geometry>
        <mesh filename="package://p_care_description/meshes/base_link.STL"/>
      </geometry>
    </collision>
  </link>
  <joint name="hip" type="revolute">
    <origin xyz="0 0 0.498"/>
    <parent link="LIOc_base_link"/>
    <child link="hip"/>
    <limit effort="1.09" lower="-1.74532925199" upper="1.74532925199" velocity="0.523598775598"/>
    <axis xyz="0 0 1"/>
  </joint>
  <link name="hip">
    <inertial>
      <origin rpy="0 0 0" xyz="-0.000129164615674658 -0.0650850183395308 0.216920107164484"/>
      <mass value="42.2499541196203"/>
      <inertia ixx="2.19278239601341" ixy="-0.00608161487223685" ixz="-0.000366786945712441" iyy="2.04392192430378" iyz="-0.137313138030081" izz="1.93900754024424"/>
    </inertial>
    <visual>
      <geometry>
        <mesh filename="package://p_care_description/meshes/hip.STL"/>
      </geometry>
      <material name="white"/>
    </visual>
    <collision>
      <geometry>
        <mesh filename="package://p_care_description/meshes/hip.STL"/>
      </geometry>
    </collision>
  </link>
  <joint name="torso" type="revolute">
    <origin xyz="0 0 0.172"/>
    <parent link="hip"/>
    <child link="torso"/>
    <limit effort="1.09" lower="-0.610865238198" upper="0.0" velocity="0.349065850399"/>
    <axis xyz="0 -1 0"/>
  </joint>
  <link name="torso">
    <inertial>
      <origin rpy="0 0 0" xyz="-0.000129164615674658 -0.0650850183395308 0.216920107164484"/>
      <mass value="42.2499541196203"/>
      <inertia ixx="2.19278239601341" ixy="-0.00608161487223685" ixz="-0.000366786945712441" iyy="2.04392192430378" iyz="-0.137313138030081" izz="1.93900754024424"/>
    </inertial>
    <visual>
      <geometry>
        <mesh filename="package://p_care_description/meshes/torso.STL"/>
      </geometry>
      <material name="white"/>
    </visual>
    <collision>
      <geometry>
        <mesh filename="package://p_care_description/meshes/torso.STL"/>
      </geometry>
    </collision>
  </link>
  <joint name="head" type="revolute">
    <origin xyz="0 0 0.45768"/>
    <parent link="torso"/>
    <child link="head"/>
    <limit effort="1.09" lower="-1.57079632679" upper="1.57079632679" velocity="0.523598775598"/>
    <axis xyz="0 0 1"/>
  </joint>
  <link name="head">
    <inertial>
      <origin rpy="0 0 0" xyz="-0.000129164615674658 -0.0650850183395308 0.216920107164484"/>
      <mass value="42.2499541196203"/>
      <inertia ixx="2.19278239601341" ixy="-0.00608161487223685" ixz="-0.000366786945712441" iyy="2.04392192430378" iyz="-0.137313138030081" izz="1.93900754024424"/>
    </inertial>
    <visual>
      <geometry>
        <mesh filename="package://p_care_description/meshes/head.STL"/>
      </geometry>
      <material name="white"/>
    </visual>
    <collision>
      <geometry>
        <mesh filename="package://p_care_description/meshes/head.STL"/>
      </geometry>
    </collision>
  </link>
  <joint name="left_joint1" type="revolute">
    <origin rpy="-1.57079632679 0 0" xyz="0 0.0859 0.366"/>
    <parent link="torso"/>
    <child link="left_link12"/>
    <limit effort="1.09" lower="-2.96705972839" upper="2.96705972839" velocity="0.829031394697"/>
    <axis xyz="0 0 1"/>
  </joint>
  <link name="left_link12">
    <inertial>
      <origin rpy="0 0 0" xyz="8.71294630254049E-05 0.277951295685675 -0.00113740271757783"/>
      <mass value="3.652"/>
      <inertia ixx="0.06656" ixy="1e-05" ixz="1e-05" iyy="0.0661" iyz="0.00952" izz="0.0076"/>
    </inertial>
    <visual>
      <geometry>
        <mesh filename="package://p_arm_description/meshes/p_care_left/link12.STL"/>
      </geometry>
      <material name="blue"/>
    </visual>
    <collision>
      <geometry>
        <mesh filename="package://p_arm_description/meshes/p_care_left/link12.STL"/>
      </geometry>
    </collision>
  </link>
  <joint name="left_joint2" type="revolute">
    <origin xyz="0 0 0.1505"/>
    <parent link="left_link12"/>
    <child link="left_link23"/>
    <limit effort="1.09" lower="-0.698131700798" upper="1.91986217719" velocity="0.829031394697"/>
    <axis xyz="0 1 0"/>
  </joint>
  <link name="left_link23">
    <inertial>
      <origin xyz="8.71294630254052E-05 0.000951295697065868 -0.00113740271757783"/>
      <mass value="3.52"/>
      <inertia ixx="0.18406" ixy="2e-05" ixz="-8e-05" iyy="0.18142" iyz="0.01932" izz="0.00841"/>
    </inertial>
    <visual>
      <geometry>
        <mesh filename="package://p_arm_description/meshes/p_care_left/link23.STL"/>
      </geometry>
      <material name="white"/>
    </visual>
    <collision>
      <geometry>
        <mesh filename="package://p_arm_description/meshes/p_care_left/link23.STL"/>
      </geometry>
    </collision>
  </link>
  <joint name="left_joint3" type="revolute">
    <origin xyz="0 0 0.29"/>
    <parent link="left_link23"/>
    <child link="left_link34"/>
    <limit effort="1.09" lower="-0.698131700798" upper="2.00712863979" velocity="0.829031394697"/>
    <axis xyz="0 1 0"/>
  </joint>
  <link name="left_link34">
    <inertial>
      <origin rpy="0 0 0" xyz="8.71294630254052E-05 -0.313548704302934 -0.00113740271757783"/>
      <mass value="1.626"/>
      <inertia ixx="0.02372" ixy="-2e-05" ixz="4e-05" iyy="0.02243" iyz="0.00024" izz="0.0343"/>
    </inertial>
    <visual>
      <geometry>
        <mesh filename="package://p_arm_description/meshes/p_care_left/link34.STL"/>
      </geometry>
      <material name="blue"/>
    </visual>
    <collision>
      <geometry>
        <mesh filename="package://p_arm_description/meshes/p_care_left/link34.STL"/>
      </geometry>
    </collision>
  </link>
  <joint name="left_joint4" type="revolute">
    <origin xyz="0 0 0.1645"/>
    <parent link="left_link34"/>
    <child link="left_link45"/>
    <limit effort="0.3275" lower="-2.96705972839" upper="2.96705972839" velocity="0.829031394697"/>
    <axis xyz="0 0 1"/>
  </joint>
  <link name="left_link45">
    <inertial>
      <origin rpy="0 0 0" xyz="8.71294630254052E-05 -0.313548704302934 -0.00113740271757783"/>
      <mass value="1.516"/>
      <inertia ixx="0.02488" ixy="2e-05" ixz="3e-05" iyy="0.02409" iyz="0.00398" izz="0.00272"/>
    </inertial>
    <visual>
      <geometry>
        <mesh filename="package://p_arm_description/meshes/p_care_left/link45.STL"/>
      </geometry>
      <material name="white"/>
    </visual>
    <collision>
      <geometry>
        <mesh filename="package://p_arm_description/meshes/p_care_left/link45.STL"/>
      </geometry>
    </collision>
  </link>
  <joint name="left_joint5" type="revolute">
    <origin xyz="0 0 0.1455"/>
    <parent link="left_link45"/>
    <child link="left_link56"/>
    <limit effort="0.3275" lower="-2.00712863979" upper="2.00712863979" velocity="0.829031394697"/>
    <axis xyz="0 1 0"/>
  </joint>
  <link name="left_link56">
    <inertial>
      <origin xyz="-8.71294630254049E-05 -0.588048704302934 0.00113740271757783"/>
      <mass value="1.417"/>
      <inertia ixx="0.01351" ixy="-2e-05" ixz="-3e-05" iyy="0.01261" iyz="-0.00012" izz="0.00274"/>
    </inertial>
    <visual>
      <geometry>
        <mesh filename="package://p_arm_description/meshes/p_care_left/link56.STL"/>
      </geometry>
      <material name="blue"/>
    </visual>
    <collision>
      <geometry>
        <mesh filename="package://p_arm_description/meshes/p_care_left/link56.STL"/>
      </geometry>
    </collision>
  </link>
  <joint name="left_joint6" type="revolute">
    <origin xyz="0 0 0.129"/>
    <parent link="left_link56"/>
    <child link="left_link6G"/>
    <limit effort="0.179324" lower="-2.96705972839" upper="2.96705972839" velocity="1.65806278939"/>
    <axis xyz="0 0 1"/>
  </joint>
  <link name="left_link6G">
    <inertial>
      <origin xyz="-0.00113740271757783 0.588048704302934 8.7129463025477E-05"/>
      <mass value="0.435"/>
      <inertia ixx="0.00079" ixy="0.0" ixz="0.0" iyy="0.00086" iyz="-1e-05" izz="0.00084"/>
    </inertial>
    <visual>
      <geometry>
        <mesh filename="package://p_arm_description/meshes/p_care_left/link6G.STL"/>
      </geometry>
      <material name="white"/>
    </visual>
    <collision>
      <geometry>
        <mesh filename="package://p_arm_description/meshes/p_care_left/link6G.STL"/>
      </geometry>
    </collision>
  </link>
  <joint name="left_gripper_interface_joint" type="fixed">
    <origin xyz="0 0 0.046"/>
    <parent link="left_link6G"/>
    <child link="left_gripper_interface_link"/>
  </joint>
  <link name="left_gripper_interface_link"/>
  <joint name="right_joint1" type="revolute">
    <origin rpy="-1.57079632679 0 3.14159265359" xyz="0 -0.0859 0.366"/>
    <parent link="torso"/>
    <child link="right_link12"/>
    <limit effort="1.09" lower="-2.96705972839" upper="2.96705972839" velocity="0.829031394697"/>
    <axis xyz="0 0 1"/>
  </joint>
  <link name="right_link12">
    <inertial>
      <origin rpy="0 0 0" xyz="8.71294630254049E-05 0.277951295685675 -0.00113740271757783"/>
      <mass value="3.652"/>
      <inertia ixx="0.06656" ixy="1e-05" ixz="1e-05" iyy="0.0661" iyz="0.00952" izz="0.0076"/>
    </inertial>
    <visual>
      <geometry>
        <mesh filename="package://p_arm_description/meshes/p_care_right/link12.STL"/>
      </geometry>
      <material name="blue"/>
    </visual>
    <collision>
      <geometry>
        <mesh filename="package://p_arm_description/meshes/p_care_right/link12.STL"/>
      </geometry>
    </collision>
  </link>
  <joint name="right_joint2" type="revolute">
    <origin xyz="0 0 0.1505"/>
    <parent link="right_link12"/>
    <child link="right_link23"/>
    <limit effort="1.09" lower="-1.91986217719" upper="0.698131700798" velocity="0.829031394697"/>
    <axis xyz="0 1 0"/>
  </joint>
  <link name="right_link23">
    <inertial>
      <origin xyz="8.71294630254052E-05 0.000951295697065868 -0.00113740271757783"/>
      <mass value="3.52"/>
      <inertia ixx="0.18406" ixy="2e-05" ixz="-8e-05" iyy="0.18142" iyz="0.01932" izz="0.00841"/>
    </inertial>
    <visual>
      <geometry>
        <mesh filename="package://p_arm_description/meshes/p_care_right/link23.STL"/>
      </geometry>
      <material name="white"/>
    </visual>
    <collision>
      <geometry>
        <mesh filename="package://p_arm_description/meshes/p_care_right/link23.STL"/>
      </geometry>
    </collision>
  </link>
  <joint name="right_joint3" type="revolute">
    <origin xyz="0 0 0.29"/>
    <parent link="right_link23"/>
    <child link="right_link34"/>
    <limit effort="1.09" lower="-2.00712863979" upper="0.698131700798" velocity="0.829031394697"/>
    <axis xyz="0 1 0"/>
  </joint>
  <link name="right_link34">
    <inertial>
      <origin rpy="0 0 0" xyz="8.71294630254052E-05 -0.313548704302934 -0.00113740271757783"/>
      <mass value="1.626"/>
      <inertia ixx="0.02372" ixy="-2e-05" ixz="4e-05" iyy="0.02243" iyz="0.00024" izz="0.0343"/>
    </inertial>
    <visual>
      <geometry>
        <mesh filename="package://p_arm_description/meshes/p_care_right/link34.STL"/>
      </geometry>
      <material name="blue"/>
    </visual>
    <collision>
      <geometry>
        <mesh filename="package://p_arm_description/meshes/p_care_right/link34.STL"/>
      </geometry>
    </collision>
  </link>
  <joint name="right_joint4" type="revolute">
    <origin xyz="0 0 0.1645"/>
    <parent link="right_link34"/>
    <child link="right_link45"/>
    <limit effort="0.3275" lower="-2.96705972839" upper="2.96705972839" velocity="0.829031394697"/>
    <axis xyz="0 0 1"/>
  </joint>
  <link name="right_link45">
    <inertial>
      <origin rpy="0 0 0" xyz="8.71294630254052E-05 -0.313548704302934 -0.00113740271757783"/>
      <mass value="1.516"/>
      <inertia ixx="0.02488" ixy="2e-05" ixz="3e-05" iyy="0.02409" iyz="0.00398" izz="0.00272"/>
    </inertial>
    <visual>
      <geometry>
        <mesh filename="package://p_arm_description/meshes/p_care_right/link45.STL"/>
      </geometry>
      <material name="white"/>
    </visual>
    <collision>
      <geometry>
        <mesh filename="package://p_arm_description/meshes/p_care_right/link45.STL"/>
      </geometry>
    </collision>
  </link>
  <joint name="right_joint5" type="revolute">
    <origin xyz="0 0 0.1455"/>
    <parent link="right_link45"/>
    <child link="right_link56"/>
    <limit effort="0.3275" lower="-2.00712863979" upper="2.00712863979" velocity="0.829031394697"/>
    <axis xyz="0 1 0"/>
  </joint>
  <link name="right_link56">
    <inertial>
      <origin xyz="-8.71294630254049E-05 -0.588048704302934 0.00113740271757783"/>
      <mass value="1.417"/>
      <inertia ixx="0.01351" ixy="-2e-05" ixz="-3e-05" iyy="0.01261" iyz="-0.00012" izz="0.00274"/>
    </inertial>
    <visual>
      <geometry>
        <mesh filename="package://p_arm_description/meshes/p_care_right/link56.STL"/>
      </geometry>
      <material name="blue"/>
    </visual>
    <collision>
      <geometry>
        <mesh filename="package://p_arm_description/meshes/p_care_right/link56.STL"/>
      </geometry>
    </collision>
  </link>
  <joint name="right_joint6" type="revolute">
    <origin xyz="0 0 0.129"/>
    <parent link="right_link56"/>
    <child link="right_link6G"/>
    <limit effort="0.179324" lower="-2.96705972839" upper="2.96705972839" velocity="1.65806278939"/>
    <axis xyz="0 0 1"/>
  </joint>
  <link name="right_link6G">
    <inertial>
      <origin xyz="-0.00113740271757783 0.588048704302934 8.7129463025477E-05"/>
      <mass value="0.435"/>
      <inertia ixx="0.00079" ixy="0.0" ixz="0.0" iyy="0.00086" iyz="-1e-05" izz="0.00084"/>
    </inertial>
    <visual>
      <geometry>
        <mesh filename="package://p_arm_description/meshes/p_care_right/link6G.STL"/>
      </geometry>
      <material name="white"/>
    </visual>
    <collision>
      <geometry>
        <mesh filename="package://p_arm_description/meshes/p_care_right/link6G.STL"/>
      </geometry>
    </collision>
  </link>
  <joint name="right_gripper_interface_joint" type="fixed">
    <origin xyz="0 0 0.046"/>
    <parent link="right_link6G"/>
    <child link="right_gripper_interface_link"/>
  </joint>
  <link name="right_gripper_interface_link"/>
  <!-- Main body of the gripper. -->
  <joint name="left_p_grip_connector" type="fixed">
    <origin rpy="0 0 0" xyz="0 0 0"/>
    <parent link="left_gripper_interface_link"/>
    <child link="left_gripper_link"/>
  </joint>
  <link name="left_gripper_link">
    <inertial>
      <origin xyz="2.24196111270369E-06 -0.00408460946644196 -0.0510660065280277"/>
      <mass value="0.82454352978473"/>
      <inertia ixx="0.00151927417232363" ixy="-3.02654547820246E-07" ixz="-4.4543064624827E-08" iyy="0.00163894166884312" iyz="-2.0883019834409E-05" izz="0.00153211830480003"/>
    </inertial>
    <visual>
      <geometry>
        <mesh filename="package://p_grip_description/meshes/p_care_left/p_grip.STL"/>
      </geometry>
      <material name="blue"/>
    </visual>
    <collision>
      <geometry>
        <mesh filename="package://p_grip_description/meshes/p_care_left/p_grip.STL"/>
      </geometry>
    </collision>
  </link>
  <!-- The left finger can be actuated via ROS. -->
  <joint name="left_gripper_joint" type="revolute">
    <origin rpy="3.14 -1.57  0" xyz="0 -0.01132 0.092783"/>
    <parent link="left_gripper_link"/>
    <child link="left_left_finger"/>
    <limit effort="0.2807" lower="0.0" upper="0.523598775598" velocity="2.61799387799"/>
    <axis xyz="0 0 1"/>
  </joint>
  <link name="left_left_finger">
    <visual>
      <origin rpy="0 0 0"/>
      <geometry>
        <mesh filename="package://p_grip_description/meshes/p_care_left/finger.STL"/>
      </geometry>
      <material name="black"/>
    </visual>
    <collision>
      <origin rpy="0 0 0"/>
      <geometry>
        <mesh filename="package://p_grip_description/meshes/p_care_left/finger.STL"/>
      </geometry>
    </collision>
  </link>
  <joint name="left_left_finger_tip_joint" type="fixed">
    <axis xyz="0 0 1"/>
    <limit effort="1000.0" lower="0" upper="0.52" velocity="170"/>
    <origin xyz="0.05689 0.01398 0"/>
    <parent link="left_left_finger"/>
    <child link="left_left_finger_tip"/>
  </joint>
  <link name="left_left_finger_tip">
    <visual>
      <origin rpy="0 0 0"/>
      <geometry>
        <mesh filename="package://p_grip_description/meshes/p_care_left/finger_tip.STL"/>
      </geometry>
      <material name="white"/>
    </visual>
    <collision>
      <origin rpy="0 0 0"/>
      <geometry>
        <mesh filename="package://p_grip_description/meshes/p_care_left/finger_tip.STL"/>
      </geometry>
    </collision>
  </link>
  <!-- The right finger simply mirrors the left one. -->
  <joint name="left_passive_gripper_joint" type="revolute">
    <mimic joint="left_gripper_joint" multiplier="-1" offset="0"/>
    <origin rpy="3.14 -1.57 0" xyz="0 0.01132 0.092783"/>
    <parent link="left_gripper_link"/>
    <child link="left_right_finger"/>
    <limit effort="1000.0" lower="0" upper="0.52" velocity="170"/>
    <axis xyz="0 0 1"/>
  </joint>
  <link name="left_right_finger">
    <visual>
      <origin rpy="3.14159265359 0 0"/>
      <geometry>
        <mesh filename="package://p_grip_description/meshes/p_care_left/finger.STL"/>
      </geometry>
      <material name="black"/>
    </visual>
    <collision>
      <origin rpy="3.14159265359 0 0"/>
      <geometry>
        <mesh filename="package://p_grip_description/meshes/p_care_left/finger.STL"/>
      </geometry>
    </collision>
  </link>
  <joint name="left_right_finger_tip_joint" type="fixed">
    <origin xyz="0.05689 -0.01398 0"/>
    <parent link="left_right_finger"/>
    <child link="left_right_finger_tip"/>
    <limit effort="1000.0" lower="0" upper="0.52" velocity="170"/>
    <axis xyz="0 0 1"/>
  </joint>
  <link name="left_right_finger_tip">
    <visual>
      <origin rpy="3.14159265359 0 0"/>
      <geometry>
        <mesh filename="package://p_grip_description/meshes/p_care_left/finger_tip.STL"/>
      </geometry>
      <material name="white"/>
    </visual>
    <collision>
      <origin rpy="3.14159265359 0 0"/>
      <geometry>
        <mesh filename="package://p_grip_description/meshes/p_care_left/finger_tip.STL"/>
      </geometry>
    </collision>
  </link>
  <!-- The tool center point is used for kinematics and path planning. -->
  <joint name="left_tcp_joint" type="fixed">
    <origin rpy="3.14 -1.57  0" xyz="0 0 0.215"/>
    <parent link="left_gripper_link"/>
    <child link="left_tcp_link"/>
  </joint>
  <link name="left_tcp_link"/>
  <!-- Main body of the gripper. -->
  <joint name="right_p_grip_connector" type="fixed">
    <origin rpy="0 0 0" xyz="0 0 0"/>
    <parent link="right_gripper_interface_link"/>
    <child link="right_gripper_link"/>
  </joint>
  <link name="right_gripper_link">
    <inertial>
      <origin xyz="2.24196111270369E-06 -0.00408460946644196 -0.0510660065280277"/>
      <mass value="0.82454352978473"/>
      <inertia ixx="0.00151927417232363" ixy="-3.02654547820246E-07" ixz="-4.4543064624827E-08" iyy="0.00163894166884312" iyz="-2.0883019834409E-05" izz="0.00153211830480003"/>
    </inertial>
    <visual>
      <geometry>
        <mesh filename="package://p_grip_description/meshes/p_care_right/p_grip.STL"/>
      </geometry>
      <material name="blue"/>
    </visual>
    <collision>
      <geometry>
        <mesh filename="package://p_grip_description/meshes/p_care_right/p_grip.STL"/>
      </geometry>
    </collision>
  </link>
  <!-- The left finger can be actuated via ROS. -->
  <joint name="right_gripper_joint" type="revolute">
    <origin rpy="3.14 -1.57  0" xyz="0 -0.01132 0.092783"/>
    <parent link="right_gripper_link"/>
    <child link="right_left_finger"/>
    <limit effort="0.2807" lower="0.0" upper="0.523598775598" velocity="2.61799387799"/>
    <axis xyz="0 0 1"/>
  </joint>
  <link name="right_left_finger">
    <visual>
      <origin rpy="0 0 0"/>
      <geometry>
        <mesh filename="package://p_grip_description/meshes/p_care_right/finger.STL"/>
      </geometry>
      <material name="black"/>
    </visual>
    <collision>
      <origin rpy="0 0 0"/>
      <geometry>
        <mesh filename="package://p_grip_description/meshes/p_care_right/finger.STL"/>
      </geometry>
    </collision>
  </link>
  <joint name="right_left_finger_tip_joint" type="fixed">
    <axis xyz="0 0 1"/>
    <limit effort="1000.0" lower="0" upper="0.52" velocity="170"/>
    <origin xyz="0.05689 0.01398 0"/>
    <parent link="right_left_finger"/>
    <child link="right_left_finger_tip"/>
  </joint>
  <link name="right_left_finger_tip">
    <visual>
      <origin rpy="0 0 0"/>
      <geometry>
        <mesh filename="package://p_grip_description/meshes/p_care_right/finger_tip.STL"/>
      </geometry>
      <material name="white"/>
    </visual>
    <collision>
      <origin rpy="0 0 0"/>
      <geometry>
        <mesh filename="package://p_grip_description/meshes/p_care_right/finger_tip.STL"/>
      </geometry>
    </collision>
  </link>
  <!-- The right finger simply mirrors the left one. -->
  <joint name="right_passive_gripper_joint" type="revolute">
    <mimic joint="right_gripper_joint" multiplier="-1" offset="0"/>
    <origin rpy="3.14 -1.57 0" xyz="0 0.01132 0.092783"/>
    <parent link="right_gripper_link"/>
    <child link="right_right_finger"/>
    <limit effort="1000.0" lower="0" upper="0.52" velocity="170"/>
    <axis xyz="0 0 1"/>
  </joint>
  <link name="right_right_finger">
    <visual>
      <origin rpy="3.14159265359 0 0"/>
      <geometry>
        <mesh filename="package://p_grip_description/meshes/p_care_right/finger.STL"/>
      </geometry>
      <material name="black"/>
    </visual>
    <collision>
      <origin rpy="3.14159265359 0 0"/>
      <geometry>
        <mesh filename="package://p_grip_description/meshes/p_care_right/finger.STL"/>
      </geometry>
    </collision>
  </link>
  <joint name="right_right_finger_tip_joint" type="fixed">
    <origin xyz="0.05689 -0.01398 0"/>
    <parent link="right_right_finger"/>
    <child link="right_right_finger_tip"/>
    <limit effort="1000.0" lower="0" upper="0.52" velocity="170"/>
    <axis xyz="0 0 1"/>
  </joint>
  <link name="right_right_finger_tip">
    <visual>
      <origin rpy="3.14159265359 0 0"/>
      <geometry>
        <mesh filename="package://p_grip_description/meshes/p_care_right/finger_tip.STL"/>
      </geometry>
      <material name="white"/>
    </visual>
    <collision>
      <origin rpy="3.14159265359 0 0"/>
      <geometry>
        <mesh filename="package://p_grip_description/meshes/p_care_right/finger_tip.STL"/>
      </geometry>
    </collision>
  </link>
  <!-- The tool center point is used for kinematics and path planning. -->
  <joint name="right_tcp_joint" type="fixed">
    <origin rpy="3.14 -1.57  0" xyz="0 0 0.215"/>
    <parent link="right_gripper_link"/>
    <child link="right_tcp_link"/>
  </joint>
  <link name="right_tcp_link"/>
  <joint name="r200_camera_chest_housing_joint" type="fixed">
    <origin rpy="0 0.157079632679 0" xyz="0.095874 0 0.415665"/>
    <parent link="torso"/>
    <child link="r200_camera_chest_housing_frame"/>
  </joint>
  <!--TODO: verify intertial and collision parameters -->
  <link name="r200_camera_chest_housing_frame">
    <visual>
      <origin rpy="1.57079632679 0 -1.57079632679" xyz="0 0 0"/>
      <geometry>
        <mesh filename="package://p_camera_description/meshes/r200.stl" scale="0.001 0.001 0.001"/>
      </geometry>
    </visual>
    <collision>
      <origin rpy="0 0 0" xyz="0 0 0"/>
      <geometry>
        <box size="0.0130 0.0567 0.0118"/>
      </geometry>
    </collision>
    <!-- This inertial field doesn't contain reliable data!! -->
    <inertial>
      <mass value="0.564"/>
      <origin xyz="0 0 0"/>
      <inertia ixx="0.003881243" ixy="0.0" ixz="0.0" iyy="0.000498940" iyz="0.0" izz="0.003879257"/>
    </inertial>
  </link>
  <joint name="camera_chest_link_joint" type="fixed">
    <origin rpy="0 0 0" xyz="0 -0.056 0.0025"/>
    <parent link="r200_camera_chest_housing_frame"/>
    <child link="camera_chest_link_mount"/>
  </joint>
  <link name="camera_chest_link_mount"/>
  <joint name="r200_camera_base_housing_joint" type="fixed">
    <origin rpy="0 0.174532925199 0" xyz="0.1185 0 0.35876"/>
    <parent link="LIOc_base_link"/>
    <child link="r200_camera_base_housing_frame"/>
  </joint>
  <!--TODO: verify intertial and collision parameters -->
  <link name="r200_camera_base_housing_frame">
    <visual>
      <origin rpy="1.57079632679 0 -1.57079632679" xyz="0 0 0"/>
      <geometry>
        <mesh filename="package://p_camera_description/meshes/r200.stl" scale="0.001 0.001 0.001"/>
      </geometry>
    </visual>
    <collision>
      <origin rpy="0 0 0" xyz="0 0 0"/>
      <geometry>
        <box size="0.0130 0.0567 0.0118"/>
      </geometry>
    </collision>
    <!-- This inertial field doesn't contain reliable data!! -->
    <inertial>
      <mass value="0.564"/>
      <origin xyz="0 0 0"/>
      <inertia ixx="0.003881243" ixy="0.0" ixz="0.0" iyy="0.000498940" iyz="0.0" izz="0.003879257"/>
    </inertial>
  </link>
  <joint name="camera_base_link_joint" type="fixed">
    <origin rpy="0 0 0" xyz="0 -0.056 0.0025"/>
    <parent link="r200_camera_base_housing_frame"/>
    <child link="camera_base_link_mount"/>
  </joint>
  <link name="camera_base_link_mount"/>
  <joint name="r200_camera_head_front_housing_joint" type="fixed">
    <origin rpy="0 -0.320791516517 0" xyz="0.08244 0 0.28125"/>
    <parent link="head"/>
    <child link="r200_camera_head_front_housing_frame"/>
  </joint>
  <!--TODO: verify intertial and collision parameters -->
  <link name="r200_camera_head_front_housing_frame">
    <visual>
      <origin rpy="1.57079632679 0 -1.57079632679" xyz="0 0 0"/>
      <geometry>
        <mesh filename="package://p_camera_description/meshes/r200.stl" scale="0.001 0.001 0.001"/>
      </geometry>
    </visual>
    <collision>
      <origin rpy="0 0 0" xyz="0 0 0"/>
      <geometry>
        <box size="0.0130 0.0567 0.0118"/>
      </geometry>
    </collision>
    <!-- This inertial field doesn't contain reliable data!! -->
    <inertial>
      <mass value="0.564"/>
      <origin xyz="0 0 0"/>
      <inertia ixx="0.003881243" ixy="0.0" ixz="0.0" iyy="0.000498940" iyz="0.0" izz="0.003879257"/>
    </inertial>
  </link>
  <joint name="camera_head_front_link_joint" type="fixed">
    <origin rpy="0 0 0" xyz="0 -0.056 0.0025"/>
    <parent link="r200_camera_head_front_housing_frame"/>
    <child link="camera_head_front_link_mount"/>
  </joint>
  <link name="camera_head_front_link_mount"/>
  <joint name="r200_camera_head_rear_housing_joint" type="fixed">
    <origin rpy="0 0 3.14159265359" xyz="-0.13392 0 0.15104"/>
    <parent link="head"/>
    <child link="r200_camera_head_rear_housing_frame"/>
  </joint>
  <!--TODO: verify intertial and collision parameters -->
  <link name="r200_camera_head_rear_housing_frame">
    <visual>
      <origin rpy="1.57079632679 0 -1.57079632679" xyz="0 0 0"/>
      <geometry>
        <mesh filename="package://p_camera_description/meshes/r200.stl" scale="0.001 0.001 0.001"/>
      </geometry>
    </visual>
    <collision>
      <origin rpy="0 0 0" xyz="0 0 0"/>
      <geometry>
        <box size="0.0130 0.0567 0.0118"/>
      </geometry>
    </collision>
    <!-- This inertial field doesn't contain reliable data!! -->
    <inertial>
      <mass value="0.564"/>
      <origin xyz="0 0 0"/>
      <inertia ixx="0.003881243" ixy="0.0" ixz="0.0" iyy="0.000498940" iyz="0.0" izz="0.003879257"/>
    </inertial>
  </link>
  <joint name="camera_head_rear_link_joint" type="fixed">
    <origin rpy="0 0 0" xyz="0 -0.056 0.0025"/>
    <parent link="r200_camera_head_rear_housing_frame"/>
    <child link="camera_head_rear_link_mount"/>
  </joint>
  <link name="camera_head_rear_link_mount"/>
  <joint name="r200_camera_gripper_right_housing_joint" type="fixed">
    <origin rpy="-3.14159265359 0.0872664625997 0" xyz="-0.11 0 -0.052"/>
    <parent link="right_tcp_link"/>
    <child link="r200_camera_gripper_right_housing_frame"/>
  </joint>
  <!--TODO: verify intertial and collision parameters -->
  <link name="r200_camera_gripper_right_housing_frame">
    <visual>
      <origin rpy="1.57079632679 0 -1.57079632679" xyz="0 0 0"/>
      <geometry>
        <mesh filename="package://p_camera_description/meshes/r200.stl" scale="0.001 0.001 0.001"/>
      </geometry>
    </visual>
    <collision>
      <origin rpy="0 0 0" xyz="0 0 0"/>
      <geometry>
        <box size="0.0130 0.0567 0.0118"/>
      </geometry>
    </collision>
    <!-- This inertial field doesn't contain reliable data!! -->
    <inertial>
      <mass value="0.564"/>
      <origin xyz="0 0 0"/>
      <inertia ixx="0.003881243" ixy="0.0" ixz="0.0" iyy="0.000498940" iyz="0.0" izz="0.003879257"/>
    </inertial>
  </link>
  <joint name="camera_gripper_right_link_joint" type="fixed">
    <origin rpy="0 0 0" xyz="0 -0.056 0.0025"/>
    <parent link="r200_camera_gripper_right_housing_frame"/>
    <child link="camera_gripper_right_link_mount"/>
  </joint>
  <link name="camera_gripper_right_link_mount"/>
  <joint name="r200_camera_gripper_left_housing_joint" type="fixed">
    <origin rpy="0 -0.0872664625997 0" xyz="-0.11 0 0.052"/>
    <parent link="left_tcp_link"/>
    <child link="r200_camera_gripper_left_housing_frame"/>
  </joint>
  <!--TODO: verify intertial and collision parameters -->
  <link name="r200_camera_gripper_left_housing_frame">
    <visual>
      <origin rpy="1.57079632679 0 -1.57079632679" xyz="0 0 0"/>
      <geometry>
        <mesh filename="package://p_camera_description/meshes/r200.stl" scale="0.001 0.001 0.001"/>
      </geometry>
    </visual>
    <collision>
      <origin rpy="0 0 0" xyz="0 0 0"/>
      <geometry>
        <box size="0.0130 0.0567 0.0118"/>
      </geometry>
    </collision>
    <!-- This inertial field doesn't contain reliable data!! -->
    <inertial>
      <mass value="0.564"/>
      <origin xyz="0 0 0"/>
      <inertia ixx="0.003881243" ixy="0.0" ixz="0.0" iyy="0.000498940" iyz="0.0" izz="0.003879257"/>
    </inertial>
  </link>
  <joint name="camera_gripper_left_link_joint" type="fixed">
    <origin rpy="0 0 0" xyz="0 -0.056 0.0025"/>
    <parent link="r200_camera_gripper_left_housing_frame"/>
    <child link="camera_gripper_left_link_mount"/>
  </joint>
  <link name="camera_gripper_left_link_mount"/>
</robot>
