<?xml version="1.0" ?>
<!-- =================================================================================== -->
<!-- |    This document was autogenerated by xacro from LIO.urdf.xacro                 | -->
<!-- |    EDITING THIS FILE BY HAND IS NOT RECOMMENDED                                 | -->
<!-- =================================================================================== -->
<robot name="lio">
  <material name="blue">
    <color rgba="0.12549019607843137 0.2784313725490196 0.43529411764705883 1"/>
  </material>
  <material name="black">
    <color rgba="0 0 0 1"/>
  </material>
  <material name="white">
    <color rgba="1 1 1 1"/>
  </material>
  <joint name="wheel_actuated_left_joint" type="continuous">
    <parent link="base_footprint"/>
    <child link="wheel_actuated_left"/>
    <origin xyz="0 0.2135 0"/>
    <axis xyz="0 1 0"/>
    <limit effort="2000" velocity="1.0"/>
    <dynamics damping="0.5" friction="1.0"/>
  </joint>
  <link name="wheel_actuated_left">
    <visual>
      <geometry>
        <cylinder length="0.03" radius="0.074"/>
      </geometry>
      <origin rpy="1.5707963267948966 0 0" xyz="0 0 0"/>
      <material name="black"/>
    </visual>
    <collision>
      <geometry>
        <cylinder length="0.03" radius="0.074"/>
      </geometry>
      <origin rpy="1.5707963267948966 0 0" xyz="0 0 0"/>
    </collision>
    <inertial>
      <mass value="0.2"/>
      <inertia ixx="0.00028879999999999997" ixy="0.0" ixz="0.0" iyy="0.0005476" iyz="0.0" izz="0.00028879999999999997"/>
    </inertial>
  </link>
  <joint name="wheel_actuated_left_movement_visualizer_joint" type="fixed">
    <parent link="wheel_actuated_left"/>
    <child link="wheel_actuated_left_visualizer"/>
    <origin xyz="0 0 0"/>
    <axis xyz="0 1 0"/>
  </joint>
  <!-- to visualize movement of the wheel -->
  <link name="wheel_actuated_left_visualizer">
    <visual>
      <geometry>
        <box size="0.1 0.04 0.04"/>
      </geometry>
      <origin xyz="0 0 0"/>
      <material name="white"/>
    </visual>
    <collision>
      <geometry>
        <box size="0 0 0"/>
      </geometry>
      <origin xyz="0 0 0"/>
    </collision>
    <inertial>
      <!-- This inertial field doesn't contain reliable data!! -->
      <mass value="0.000001"/>
      <inertia ixx="0.000001" ixy="0.0" ixz="0.0" iyy="0.000001" iyz="0.0" izz="0.000001"/>
    </inertial>
  </link>
  <joint name="wheel_actuated_right_joint" type="continuous">
    <parent link="base_footprint"/>
    <child link="wheel_actuated_right"/>
    <origin xyz="0 -0.2135 0"/>
    <axis xyz="0 1 0"/>
    <limit effort="2000" velocity="1.0"/>
    <dynamics damping="0.5" friction="1.0"/>
  </joint>
  <link name="wheel_actuated_right">
    <visual>
      <geometry>
        <cylinder length="0.03" radius="0.074"/>
      </geometry>
      <origin rpy="1.5707963267948966 0 0" xyz="0 0 0"/>
      <material name="black"/>
    </visual>
    <collision>
      <geometry>
        <cylinder length="0.03" radius="0.074"/>
      </geometry>
      <origin rpy="1.5707963267948966 0 0" xyz="0 0 0"/>
    </collision>
    <inertial>
      <mass value="0.2"/>
      <inertia ixx="0.00028879999999999997" ixy="0.0" ixz="0.0" iyy="0.0005476" iyz="0.0" izz="0.00028879999999999997"/>
    </inertial>
  </link>
  <joint name="wheel_actuated_right_movement_visualizer_joint" type="fixed">
    <parent link="wheel_actuated_right"/>
    <child link="wheel_actuated_right_visualizer"/>
    <origin xyz="0 0 0"/>
    <axis xyz="0 1 0"/>
  </joint>
  <!-- to visualize movement of the wheel -->
  <link name="wheel_actuated_right_visualizer">
    <visual>
      <geometry>
        <box size="0.1 0.04 0.04"/>
      </geometry>
      <origin xyz="0 0 0"/>
      <material name="white"/>
    </visual>
    <collision>
      <geometry>
        <box size="0 0 0"/>
      </geometry>
      <origin xyz="0 0 0"/>
    </collision>
    <inertial>
      <!-- This inertial field doesn't contain reliable data!! -->
      <mass value="0.000001"/>
      <inertia ixx="0.000001" ixy="0.0" ixz="0.0" iyy="0.000001" iyz="0.0" izz="0.000001"/>
    </inertial>
  </link>
  <!-- Caster Wheel Link -->
  <link name="caster_left_wheel">
    <inertial>
      <mass value="0.03837"/>
      <origin xyz="0 0 0"/>
      <inertia ixx="0.000008221" ixy="0" ixz="0" iyy="0.000013003" iyz="0" izz="0.000008221"/>
    </inertial>
    <visual>
      <origin rpy="1.57 0 0" xyz="0 0 0"/>
      <geometry>
        <mesh filename="package://platform_description/meshes/caswheel.dae"/>
      </geometry>
    </visual>
    <collision>
      <origin rpy="1.57 0 0" xyz="0 0 0"/>
      <geometry>
        <cylinder length="0.011665" radius="0.024165"/>
      </geometry>
    </collision>
  </link>
  <!-- Caster Base Link -->
  <link name="caster_left_base">
    <inertial>
      <mass value="0.06597"/>
      <origin xyz="-0.01204 0 -0.01454"/>
      <inertia ixx="0.000039912" ixy="0" ixz="0.000017794" iyy="0.000050728" iyz="0" izz="0.000035261"/>
    </inertial>
    <visual>
      <origin rpy="0 0 0" xyz="0 0 -0.0075"/>
      <geometry>
        <cylinder length="0.015" radius="0.015"/>
      </geometry>
    </visual>
    <collision>
      <origin rpy="0 0 0" xyz="0 0 -0.0075"/>
      <geometry>
        <cylinder length="0.015" radius="0.015"/>
      </geometry>
    </collision>
  </link>
  <!-- Caster Base Link and Wheel Link Joint -->
  <joint name="caster_left_wheel_joint" type="continuous">
    <parent link="caster_left_base"/>
    <child link="caster_left_wheel"/>
    <origin rpy="0 0 0" xyz="-0.02626 0 -0.042385"/>
    <axis rpy="0 0 0" xyz="0 1 0"/>
    <dynamics friction="0.0100"/>
  </joint>
  <!-- Caster base and parent joint -->
  <joint name="caster_left_base_joint" type="continuous">
    <parent link="base_footprint"/>
    <child link="caster_left_base"/>
    <origin rpy="0 0 0" xyz="-0.5 0.16349999999999998 -0.01"/>
    <axis rpy="0 0 0" xyz="0 0 1"/>
    <dynamics friction="0.0100"/>
  </joint>
  <!-- Caster Wheel Link -->
  <link name="caster_right_wheel">
    <inertial>
      <mass value="0.03837"/>
      <origin xyz="0 0 0"/>
      <inertia ixx="0.000008221" ixy="0" ixz="0" iyy="0.000013003" iyz="0" izz="0.000008221"/>
    </inertial>
    <visual>
      <origin rpy="1.57 0 0" xyz="0 0 0"/>
      <geometry>
        <mesh filename="package://platform_description/meshes/caswheel.dae"/>
      </geometry>
    </visual>
    <collision>
      <origin rpy="1.57 0 0" xyz="0 0 0"/>
      <geometry>
        <cylinder length="0.011665" radius="0.024165"/>
      </geometry>
    </collision>
  </link>
  <!-- Caster Base Link -->
  <link name="caster_right_base">
    <inertial>
      <mass value="0.06597"/>
      <origin xyz="-0.01204 0 -0.01454"/>
      <inertia ixx="0.000039912" ixy="0" ixz="0.000017794" iyy="0.000050728" iyz="0" izz="0.000035261"/>
    </inertial>
    <visual>
      <origin rpy="0 0 0" xyz="0 0 -0.0075"/>
      <geometry>
        <cylinder length="0.015" radius="0.015"/>
      </geometry>
    </visual>
    <collision>
      <origin rpy="0 0 0" xyz="0 0 -0.0075"/>
      <geometry>
        <cylinder length="0.015" radius="0.015"/>
      </geometry>
    </collision>
  </link>
  <!-- Caster Base Link and Wheel Link Joint -->
  <joint name="caster_right_wheel_joint" type="continuous">
    <parent link="caster_right_base"/>
    <child link="caster_right_wheel"/>
    <origin rpy="0 0 0" xyz="-0.02626 0 -0.042385"/>
    <axis rpy="0 0 0" xyz="0 1 0"/>
    <dynamics friction="0.0100"/>
  </joint>
  <!-- Caster base and parent joint -->
  <joint name="caster_right_base_joint" type="continuous">
    <parent link="base_footprint"/>
    <child link="caster_right_base"/>
    <origin rpy="0 0 0" xyz="-0.5 -0.16349999999999998 -0.01"/>
    <axis rpy="0 0 0" xyz="0 0 1"/>
    <dynamics friction="0.0100"/>
  </joint>
  <link name="base_footprint">

  </link>
  <joint name="base_joint" type="fixed">
    <origin rpy="0 0 0" xyz="-0.113 0 0"/>
    <parent link="base_footprint"/>
    <child link="platform_base_link"/>
  </joint>
  <link name="platform_base_link">
    <visual>
      <geometry>
        <mesh filename="package://platform_description/meshes/platform_LIO.STL"/>
        <!-- create Lio Version c mesh, still Lio b mesh-->
      </geometry>
      <origin rpy="0 0 1.57" xyz="0 0 -0.05"/>
      <material name="white"/>
    </visual>
    <collision>
      <geometry>
        <mesh filename="package://platform_description/meshes/platform_LIO.STL"/>
      </geometry>
      <origin rpy="0 0 1.57" xyz="0 0 -0.05"/>
    </collision>
    <!-- This inertial field doesn't contain reliable data!! -->
    <inertial>
      <mass value="60.0"/>
      <origin xyz="0 0 0"/>
      <inertia ixx="0.3881243" ixy="0.0" ixz="0.0" iyy="0.898940" iyz="0.0" izz="0.3879257"/>
    </inertial>
  </link>
  <joint name="lidar_front_joint" type="fixed">
    <origin rpy="0 3.14 0" xyz="-0.25762 0.15592 -0.01"/>
    <parent link="base_footprint"/>
    <child link="lidar_front"/>
  </joint>
  <link name="lidar_front">
   </link>
  <joint name="lidar_back_joint" type="fixed">
    <origin rpy="0 3.14 3.14" xyz="-0.25762 -0.15592 -0.01"/>
    <parent link="base_footprint"/>
    <child link="lidar_back"/>
  </joint>
  <link name="lidar_back">
   </link>
  <joint name="lidar_front_joint_helper" type="fixed">
    <origin rpy="0 3.14 1.57" xyz="-0.25762 0.15592 -0.01"/>
    <parent link="base_footprint"/>
    <child link="lidar_front_helper"/>
  </joint>
  <link name="lidar_front_helper">
   </link>
  <joint name="lidar_back_joint_helper" type="fixed">
    <origin rpy="0 3.14 1.57" xyz="-0.25762 -0.15592 -0.01"/>
    <parent link="base_footprint"/>
    <child link="lidar_back_helper"/>
  </joint>
  <link name="lidar_back_helper">
   </link>
  <joint name="LIO_robot_base_link_joint" type="fixed">
    <origin rpy="0 0 0" xyz="0 0 -0.0725"/>
    <child link="LIO_base_link"/>
    <parent link="platform_base_link"/>
  </joint>
  <link name="LIO_base_link">
    <inertial>
      <origin rpy="0 0 0" xyz="-0 0 0 "/>
      <mass value="42.2499541196203"/>
      <inertia ixx="2.19278239601341" ixy="-0.00608161487223685" ixz="-0.000366786945712441" iyy="2.04392192430378" iyz="-0.137313138030081" izz="1.93900754024424"/>
    </inertial>
  </link>
  <joint name="Lio_base_joint" type="fixed">
    <origin rpy="0 0 1.57" xyz="0 0 0.2655"/>
    <parent link="LIO_base_link"/>
    <child link="LIO_robot_base_link"/>
  </joint>
  <joint name="rgbd_down_link_joint" type="fixed">
    <origin rpy=" 0 0.15 0" xyz="0.243 -0.0175 0.206"/>
    <parent link="LIO_base_link"/>
    <child link="rgbd_down_link"/>
  </joint>
  <link name="rgbd_down_link"/>
  <joint name="rgbd_up_link_joint" type="fixed">
    <origin rpy=" 3.14 -0.15 0" xyz="0.243 0.0175 0.206"/>
    <parent link="LIO_base_link"/>
    <child link="rgbd_up_link"/>
  </joint>
  <link name="rgbd_up_link"/>
  <joint name="fisheye_fisheye_base_housing_joint" type="fixed">
    <insert_block name="origin"/>
    <parent link="LIO_base_link"/>
    <child link="fisheye_fisheye_base_housing_frame"/>
  </joint>
  <!--TODO: verify intertial and collision parameters -->
  <link name="fisheye_fisheye_base_housing_frame">
    <!-- TODO fisheye not correctly placed for Lioc (under Lio in center)
      <visual>
        <origin xyz="0 0 0" rpy="${pi/2} 0 ${-pi/2}"/>
        <geometry>
          <box size="0.025 0.025 0.025" />
        </geometry>
      </visual>
      <collision>
        <origin xyz="0 0 0" rpy="0 0 0"/>
        <geometry>
          <box size="0.0130 0.0567 0.0118"/>
        </geometry>
      </collision>
      -->
    <!-- This inertial field doesn't contain reliable data!! -->
    <inertial>
      <mass value="0.564"/>
      <origin xyz="0 0 0"/>
      <inertia ixx="0.003881243" ixy="0.0" ixz="0.0" iyy="0.000498940" iyz="0.0" izz="0.003879257"/>
    </inertial>
  </link>
  <joint name="fisheye_base_link_joint" type="fixed">
    <origin rpy="0 0 0" xyz="0 -0.025 0.0025"/>
    <parent link="fisheye_fisheye_base_housing_frame"/>
    <child link="fisheye_base_link_mount"/>
  </joint>
  <link name="fisheye_base_link_mount"/>
  <joint name="lio_joint1" type="revolute">
    <origin rpy="0 0 0" xyz="0 0 0.212"/>
    <!-- <origin xyz="0 0 0.212" rpy="0 0 0" /> -->
    <parent link="LIO_robot_base_link"/>
    <child link="lio_link12"/>
    <limit effort="150" lower="-2.9670597283903604" upper="2.9670597283903604" velocity="1.658062789394613"/>
    <axis xyz="0 0 1"/>
    <dynamics damping="5.0" friction="5.0"/>
  </joint>
  <!-- <transmission name="${name}_joint1_trans">
      <type>transmission_interface/SimpleTransmission</type>
      <actuator name="${name}_joint1_motor">
      <hardwareInterface>hardware_interface/PositionJointInterface</hardwareInterface>
        <mechanicalReduction>1</mechanicalReduction>
      </actuator>
      <joint name="${name}_joint1">
        <hardwareInterface>hardware_interface/PositionJointInterface</hardwareInterface>
      </joint>
  </transmission> -->
  <link name="lio_link12">
    <inertial>
      <origin rpy="0 0 0" xyz="8.71294630254049E-05 0.0 -0.00113740271757783"/>
      <mass value="3.652"/>
      <inertia ixx="0.06656" ixy="1e-05" ixz="1e-05" iyy="0.0661" iyz="0.00952" izz="0.0076"/>
    </inertial>
    <visual>
      <geometry>
        <mesh filename="package://p_arm_description/meshes/p_rob_2R/link12.STL"/>
      </geometry>
      <material name="blue"/>
    </visual>
    <collision>
      <geometry>
        <mesh filename="package://p_arm_description/meshes/p_rob_2R/link12.STL"/>
      </geometry>
    </collision>
  </link>
  <joint name="lio_joint2" type="revolute">
    <origin xyz="0 0 0.1505"/>
    <parent link="lio_link12"/>
    <child link="lio_link23"/>
    <limit effort="150" lower="-1.9198621771937625" upper="1.9198621771937625" velocity="1.658062789394613"/>
    <axis xyz="0 1 0"/>
    <dynamics damping="10.0" friction="5.0"/>
  </joint>
  <link name="lio_link23">
    <inertial>
      <origin xyz="8.71294630254052E-05 0.000951295697065868 -0.00113740271757783"/>
      <mass value="3.52"/>
      <inertia ixx="0.18406" ixy="2e-05" ixz="-8e-05" iyy="0.18142" iyz="0.01932" izz="0.00841"/>
    </inertial>
    <visual>
      <geometry>
        <mesh filename="package://p_arm_description/meshes/p_rob_2R/link23.STL"/>
      </geometry>
      <material name="white"/>
    </visual>
    <collision>
      <geometry>
        <mesh filename="package://p_arm_description/meshes/p_rob_2R/link23.STL"/>
      </geometry>
    </collision>
  </link>
  <joint name="lio_joint3" type="revolute">
    <origin xyz="0 0 0.29"/>
    <parent link="lio_link23"/>
    <child link="lio_link34"/>
    <limit effort="150" lower="-2.007128639793479" upper="2.007128639793479" velocity="1.658062789394613"/>
    <axis xyz="0 1 0"/>
    <dynamics damping="5.0" friction="5.0"/>
  </joint>
  <link name="lio_link34">
    <inertial>
      <origin rpy="0 0 0" xyz="8.71294630254052E-05 0.0 -0.00113740271757783"/>
      <mass value="1.626"/>
      <inertia ixx="0.02372" ixy="-2e-05" ixz="4e-05" iyy="0.02243" iyz="0.00024" izz="0.0343"/>
    </inertial>
    <visual>
      <geometry>
        <mesh filename="package://p_arm_description/meshes/p_rob_2R/link34.STL"/>
      </geometry>
      <material name="blue"/>
    </visual>
    <collision>
      <geometry>
        <mesh filename="package://p_arm_description/meshes/p_rob_2R/link34.STL"/>
      </geometry>
    </collision>
  </link>
  <joint name="lio_joint4" type="revolute">
    <origin xyz="0 0 0.1645"/>
    <parent link="lio_link34"/>
    <child link="lio_link45"/>
    <limit effort="55" lower="-2.9670597283903604" upper="2.9670597283903604" velocity="1.658062789394613"/>
    <axis xyz="0 0 1"/>
    <dynamics damping="5.0" friction="5.0"/>
  </joint>
  <link name="lio_link45">
    <inertial>
      <origin rpy="0 0 0" xyz="8.71294630254052E-05 0.0 -0.00113740271757783"/>
      <mass value="1.516"/>
      <inertia ixx="0.02488" ixy="2e-05" ixz="3e-05" iyy="0.02409" iyz="0.00398" izz="0.00272"/>
    </inertial>
    <visual>
      <geometry>
        <mesh filename="package://p_arm_description/meshes/p_rob_2R/link45.STL"/>
      </geometry>
      <material name="white"/>
    </visual>
    <collision>
      <geometry>
        <mesh filename="package://p_arm_description/meshes/p_rob_2R/link45.STL"/>
      </geometry>
    </collision>
  </link>
  <joint name="lio_joint5" type="revolute">
    <origin xyz="0 0 0.1455"/>
    <parent link="lio_link45"/>
    <child link="lio_link56"/>
    <limit effort="55" lower="-2.007128639793479" upper="2.007128639793479" velocity="1.658062789394613"/>
    <axis xyz="0 1 0"/>
    <dynamics damping="5.0" friction="5.0"/>
  </joint>
  <link name="lio_link56">
    <inertial>
      <origin xyz="-8.71294630254049E-05 0.0 0.00113740271757783"/>
      <mass value="1.417"/>
      <inertia ixx="0.01351" ixy="-2e-05" ixz="-3e-05" iyy="0.01261" iyz="-0.00012" izz="0.00274"/>
    </inertial>
    <visual>
      <geometry>
        <mesh filename="package://p_arm_description/meshes/p_rob_2R/link56.STL"/>
      </geometry>
      <material name="blue"/>
    </visual>
    <collision>
      <geometry>
        <mesh filename="package://p_arm_description/meshes/p_rob_2R/link56.STL"/>
      </geometry>
    </collision>
  </link>
  <joint name="lio_joint6" type="revolute">
    <origin xyz="0 0 0.129"/>
    <parent link="lio_link56"/>
    <child link="lio_link6G"/>
    <limit effort="30" lower="-2.9670597283903604" upper="2.9670597283903604" velocity="1.658062789394613"/>
    <axis xyz="0 0 1"/>
    <dynamics damping="5.0" friction="5.0"/>
  </joint>
  <link name="lio_link6G">
    <inertial>
      <origin xyz="-0.00113740271757783 0.0 8.7129463025477E-05"/>
      <mass value="0.435"/>
      <inertia ixx="0.00079" ixy="0.0" ixz="0.0" iyy="0.00086" iyz="-1e-05" izz="0.00084"/>
    </inertial>
    <visual>
      <geometry>
        <mesh filename="package://p_arm_description/meshes/p_rob_2R/link6G.STL"/>
      </geometry>
      <material name="white"/>
    </visual>
    <collision>
      <geometry>
        <mesh filename="package://p_arm_description/meshes/p_rob_2R/link6G.STL"/>
      </geometry>
    </collision>
  </link>
  <joint name="lio_gripper_interface_joint" type="fixed">
    <origin xyz="0 0 0.046"/>
    <parent link="lio_link6G"/>
    <child link="lio_gripper_interface_link"/>
  </joint>
  <link name="lio_gripper_interface_link">
    <inertial>
      <!-- the inertia values are guessed-->
      <origin xyz="0 0 0"/>
      <mass value="0.1"/>
      <inertia ixx="0.0001" ixy="0.9" ixz="0.0" iyy="0.0001" iyz="0.0" izz="0.0001"/>
    </inertial>
  </link>
  <link name="LIO_robot_base_link">
    <inertial>
      <origin rpy="0 0 1.57" xyz="-0 0 0.2345"/>
      <mass value="42.2499541196203"/>
      <inertia ixx="2.19278239601341" ixy="-0.00608161487223685" ixz="-0.000366786945712441" iyy="2.04392192430378" iyz="-0.137313138030081" izz="1.93900754024424"/>
    </inertial>
  </link>
  <joint name="lio_back_cover_joint" type="fixed">
    <parent link="lio_gripper_interface_link"/>
    <child link="lio_back_cover"/>
  </joint>
  <link name="lio_back_cover">
    <inertial>
      <origin xyz="2.24196111270369E-06 -0.00408460946644196 -0.0510660065280277"/>
      <mass value="0.82454352978473"/>
      <inertia ixx="0.00151927417232363" ixy="-3.02654547820246E-07" ixz="-4.4543064624827E-08" iyy="0.00163894166884312" iyz="-2.0883019834409E-05" izz="0.00153211830480003"/>
    </inertial>
    <visual>
      <geometry>
        <mesh filename="package://p_grip_description/meshes/p_grip_2F/back_cover.STL"/>
      </geometry>
      <material name="white"/>
    </visual>
    <collision>
      <geometry>
        <mesh filename="package://p_grip_description/meshes/p_grip_2F/back_cover.STL"/>
      </geometry>
    </collision>
  </link>
  <!-- Main body of the gripper. -->
  <joint name="lio_p_grip_connector" type="fixed">
    <origin rpy="0 -1.57 3.14" xyz="-0.052 0 0.052"/>
    <parent link="lio_gripper_interface_link"/>
    <child link="lio_gripper_link"/>
  </joint>
  <link name="lio_gripper_link">
    <inertial>
      <origin xyz="2.24196111270369E-06 -0.00408460946644196 -0.0510660065280277"/>
      <mass value="0.82454352978473"/>
      <inertia ixx="0.00151927417232363" ixy="-3.02654547820246E-07" ixz="-4.4543064624827E-08" iyy="0.00163894166884312" iyz="-2.0883019834409E-05" izz="0.00153211830480003"/>
    </inertial>
    <visual>
      <geometry>
        <mesh filename="package://p_grip_description/meshes/p_grip_2F/p_grip.STL"/>
      </geometry>
      <material name="blue"/>
    </visual>
    <collision>
      <geometry>
        <mesh filename="package://p_grip_description/meshes/p_grip_2F/p_grip.STL"/>
      </geometry>
    </collision>
  </link>
  <!-- The left finger can be actuated via ROS. -->
  <joint name="lio_gripper_joint" type="revolute">
    <origin rpy="0 0 0" xyz="0.0645 0 0.052"/>
    <parent link="lio_gripper_link"/>
    <child link="lio_left_finger"/>
    <limit effort="50" lower="0.0" upper="0.5235987755982988" velocity="1.0471975511965976"/>
    <axis xyz="0 0 1"/>
  </joint>
  <link name="lio_left_finger">
    <inertial>
      <!-- the inertia values are guessed-->
      <origin xyz="0 0 0"/>
      <mass value="0.1"/>
      <inertia ixx="0.0001" ixy="0.9" ixz="0.0" iyy="0.0001" iyz="0.0" izz="0.0001"/>
    </inertial>
    <visual>
      <origin rpy="0 0 0"/>
      <geometry>
        <mesh filename="package://p_grip_description/meshes/p_grip_2F/finger.STL"/>
      </geometry>
      <material name="black"/>
    </visual>
    <collision>
      <origin rpy="0 0 0"/>
      <geometry>
        <mesh filename="package://p_grip_description/meshes/p_grip_2F/finger.STL"/>
      </geometry>
    </collision>
  </link>
  <!-- The right finger simply mirrors the left one. -->
  <joint name="lio_passive_gripper_joint" type="revolute">
    <mimic joint="lio_gripper_joint" multiplier="-1" offset="0"/>
    <origin rpy="0 0 0" xyz="0.0645 0 0.052"/>
    <parent link="lio_gripper_link"/>
    <child link="lio_right_finger"/>
    <limit effort="1000.0" lower="-0.5235987755982988" upper="0.0" velocity="170"/>
    <axis xyz="0 0 1"/>
  </joint>
  <link name="lio_right_finger">
    <inertial>
      <!-- the inertia values are guessed-->
      <origin xyz="0 0 0"/>
      <mass value="0.1"/>
      <inertia ixx="0.0001" ixy="0.9" ixz="0.0" iyy="0.0001" iyz="0.0" izz="0.0001"/>
    </inertial>
    <visual>
      <origin rpy="3.141592653589793 0 0"/>
      <geometry>
        <mesh filename="package://p_grip_description/meshes/p_grip_2F/finger.STL"/>
      </geometry>
      <material name="black"/>
    </visual>
    <collision>
      <origin rpy="3.141592653589793 0 0"/>
      <geometry>
        <mesh filename="package://p_grip_description/meshes/p_grip_2F/finger.STL"/>
      </geometry>
    </collision>
  </link>
  <!-- The tool center point is used for kinematics and path planning. -->
  <joint name="lio_tcp_joint" type="fixed">
    <origin rpy="0 0 0" xyz="0.189 0 0.052"/>
    <parent link="lio_gripper_link"/>
    <child link="lio_tcp_link"/>
  </joint>
  <link name="lio_tcp_link">
    <inertial>
      <!-- the inertia values are guessed-->
      <origin xyz="0 0 0"/>
      <mass value="0.1"/>
      <inertia ixx="0.0001" ixy="0.9" ixz="0.0" iyy="0.0001" iyz="0.0" izz="0.0001"/>
    </inertial>
  </link>
  <joint name="lio_tis_cam_joint" type="fixed">
    <origin rpy="-1.5707963267948966 0.0 -1.5707963267948966" xyz="-0.095 0.0 0.053"/>
    <parent link="lio_tcp_link"/>
    <child link="tis_cam"/>
  </joint>
  <link name="tis_cam">
    <inertial>
      <!-- the inertia values are guessed but needed for gazebo -->
      <origin xyz="0 0 0"/>
      <mass value="0.001"/>
      <inertia ixx="0.0001" ixy="0.9" ixz="0.0" iyy="0.0001" iyz="0.0" izz="0.0001"/>
    </inertial>
  </link>
  <!-- we need this joint and link for the camera plugin in gazebo the x is taken for camera direction -->
  <joint name="lio_tis_cam_sim_plugin_joint" type="fixed">
    <origin rpy="0 -1.5707963267948966 0" xyz="0.0 0.0 0.0"/>
    <parent link="tis_cam"/>
    <child link="tis_cam_sim_plugin"/>
  </joint>
  <link name="tis_cam_sim_plugin">
    <inertial>
      <!-- the inertia values are guessed but needed for gazebo -->
      <origin xyz="0 0 0"/>
      <mass value="0.001"/>
      <inertia ixx="0.0001" ixy="0.9" ixz="0.0" iyy="0.0001" iyz="0.0" izz="0.0001"/>
    </inertial>
  </link>
</robot>

