<?xml version="1.0" ?>
<!-- =================================================================================== -->
<!-- |    This document was autogenerated by xacro from src/lio-developments/fp_messages/fp_descriptions/lio_description/urdf/LIO.urdf.xacro | -->
<!-- |    EDITING THIS FILE BY HAND IS NOT RECOMMENDED                                 | -->
<!-- =================================================================================== -->
<robot name="lio">
  <material name="blue">
    <color rgba="0.12549019607843137 0.2784313725490196 0.43529411764705883 1"/>
  </material>
  <material name="black">
    <color rgba="0 0 0 1"/>
  </material>
  <material name="white">
    <color rgba="1 1 1 1"/>
  </material>



  <link name="base_footprint">
  
  </link>

  <joint name="lio_joint1" type="revolute">
    <origin rpy="0 0 0" xyz="0 0 0.212"/>
    <!-- <origin xyz="0 0 0.212" rpy="0 0 0" /> -->
    <parent link="base_footprint"/>
    <child link="lio_link12"/>
    <limit effort="150" lower="-2.9670597283903604" upper="2.9670597283903604" velocity="1.658062789394613"/>
    <axis xyz="0 0 1"/>
    <dynamics damping="5.0" friction="5.0"/>
  </joint>
  <!-- <transmission name="${name}_joint1_trans">
      <type>transmission_interface/SimpleTransmission</type>
      <actuator name="${name}_joint1_motor">
      <hardwareInterface>hardware_interface/PositionJointInterface</hardwareInterface>
        <mechanicalReduction>1</mechanicalReduction>
      </actuator>
      <joint name="${name}_joint1">
        <hardwareInterface>hardware_interface/PositionJointInterface</hardwareInterface>
      </joint>
  </transmission> -->
  <link name="lio_link12">
    <inertial>
      <origin rpy="0 0 0" xyz="8.71294630254049E-05 0.0 -0.00113740271757783"/>
      <mass value="3.652"/>
      <inertia ixx="0.06656" ixy="1e-05" ixz="1e-05" iyy="0.0661" iyz="0.00952" izz="0.0076"/>
    </inertial>
    <visual>
      <geometry>
        <mesh filename="package://p_arm_description/meshes/p_rob_2R/link12.STL"/>
      </geometry>
      <material name="blue"/>
    </visual>
    <collision>
      <geometry>
        <mesh filename="package://p_arm_description/meshes/p_rob_2R/link12.STL"/>
      </geometry>
    </collision>
  </link>

  <joint name="lio_joint2" type="revolute">
    <origin xyz="0 0 0.1505"/>
    <parent link="lio_link12"/>
    <child link="lio_link23"/>
    <limit effort="150" lower="-1.9198621771937625" upper="1.9198621771937625" velocity="1.658062789394613"/>
    <axis xyz="0 1 0"/>
    <dynamics damping="10.0" friction="5.0"/>
  </joint>
  <link name="lio_link23">
    <inertial>
      <origin xyz="8.71294630254052E-05 0.000951295697065868 -0.00113740271757783"/>
      <mass value="3.52"/>
      <inertia ixx="0.18406" ixy="2e-05" ixz="-8e-05" iyy="0.18142" iyz="0.01932" izz="0.00841"/>
    </inertial>
    <visual>
      <geometry>
        <mesh filename="package://p_arm_description/meshes/p_rob_2R/link23.STL"/>
      </geometry>
      <material name="white"/>
    </visual>
    <collision>
      <geometry>
        <mesh filename="package://p_arm_description/meshes/p_rob_2R/link23.STL"/>
      </geometry>
    </collision>
  </link>

  <joint name="lio_joint3" type="revolute">
    <origin xyz="0 0 0.29"/>
    <parent link="lio_link23"/>
    <child link="lio_link34"/>
    <limit effort="150" lower="-2.007128639793479" upper="2.007128639793479" velocity="1.658062789394613"/>
    <axis xyz="0 1 0"/>
    <dynamics damping="5.0" friction="5.0"/>
  </joint>
  <link name="lio_link34">
    <inertial>
      <origin rpy="0 0 0" xyz="8.71294630254052E-05 0.0 -0.00113740271757783"/>
      <mass value="1.626"/>
      <inertia ixx="0.02372" ixy="-2e-05" ixz="4e-05" iyy="0.02243" iyz="0.00024" izz="0.0343"/>
    </inertial>
    <visual>
      <geometry>
        <mesh filename="package://p_arm_description/meshes/p_rob_2R/link34.STL"/>
      </geometry>
      <material name="blue"/>
    </visual>
    <collision>
      <geometry>
        <mesh filename="package://p_arm_description/meshes/p_rob_2R/link34.STL"/>
      </geometry>
    </collision>
  </link>

  <joint name="lio_joint4" type="revolute">
    <origin xyz="0 0 0.1645"/>
    <parent link="lio_link34"/>
    <child link="lio_link45"/>
    <limit effort="55" lower="-2.9670597283903604" upper="2.9670597283903604" velocity="1.658062789394613"/>
    <axis xyz="0 0 1"/>
    <dynamics damping="5.0" friction="5.0"/>
  </joint>
  <link name="lio_link45">
    <inertial>
      <origin rpy="0 0 0" xyz="8.71294630254052E-05 0.0 -0.00113740271757783"/>
      <mass value="1.516"/>
      <inertia ixx="0.02488" ixy="2e-05" ixz="3e-05" iyy="0.02409" iyz="0.00398" izz="0.00272"/>
    </inertial>
    <visual>
      <geometry>
        <mesh filename="package://p_arm_description/meshes/p_rob_2R/link45.STL"/>
      </geometry>
      <material name="white"/>
    </visual>
    <collision>
      <geometry>
        <mesh filename="package://p_arm_description/meshes/p_rob_2R/link45.STL"/>
      </geometry>
    </collision>
  </link>

  <joint name="lio_joint5" type="revolute">
    <origin xyz="0 0 0.1455"/>
    <parent link="lio_link45"/>
    <child link="lio_link56"/>
    <limit effort="55" lower="-2.007128639793479" upper="2.007128639793479" velocity="1.658062789394613"/>
    <axis xyz="0 1 0"/>
    <dynamics damping="5.0" friction="5.0"/>
  </joint>
  <link name="lio_link56">
    <inertial>
      <origin xyz="-8.71294630254049E-05 0.0 0.00113740271757783"/>
      <mass value="1.417"/>
      <inertia ixx="0.01351" ixy="-2e-05" ixz="-3e-05" iyy="0.01261" iyz="-0.00012" izz="0.00274"/>
    </inertial>
    <visual>
      <geometry>
        <mesh filename="package://p_arm_description/meshes/p_rob_2R/link56.STL"/>
      </geometry>
      <material name="blue"/>
    </visual>
    <collision>
      <geometry>
        <mesh filename="package://p_arm_description/meshes/p_rob_2R/link56.STL"/>
      </geometry>
    </collision>
  </link>

  <joint name="lio_joint6" type="revolute">
    <origin xyz="0 0 0.129"/>
    <parent link="lio_link56"/>
    <child link="lio_link6G"/>
    <limit effort="30" lower="-2.9670597283903604" upper="2.9670597283903604" velocity="1.658062789394613"/>
    <axis xyz="0 0 1"/>
    <dynamics damping="5.0" friction="5.0"/>
  </joint>
  <link name="lio_link6G">
    <inertial>
      <origin xyz="-0.00113740271757783 0.0 8.7129463025477E-05"/>
      <mass value="0.435"/>
      <inertia ixx="0.00079" ixy="0.0" ixz="0.0" iyy="0.00086" iyz="-1e-05" izz="0.00084"/>
    </inertial>
    <visual>
      <geometry>
        <mesh filename="package://p_arm_description/meshes/p_rob_2R/link6G.STL"/>
      </geometry>
      <material name="white"/>
    </visual>
    <collision>
      <geometry>
        <mesh filename="package://p_arm_description/meshes/p_rob_2R/link6G.STL"/>
      </geometry>
    </collision>
  </link>

  <joint name="lio_gripper_interface_joint" type="fixed">
    <origin xyz="0 0 0.046"/>
    <parent link="lio_link6G"/>
    <child link="lio_gripper_interface_link"/>
  </joint>
  <link name="lio_gripper_interface_link">
    <inertial>
      <!-- the inertia values are guessed-->
      <origin xyz="0 0 0"/>
      <mass value="0.1"/>
      <inertia ixx="0.0001" ixy="0.9" ixz="0.0" iyy="0.0001" iyz="0.0" izz="0.0001"/>
    </inertial>
  </link>

  <joint name="lio_back_cover_joint" type="fixed">
    <parent link="lio_gripper_interface_link"/>
    <child link="lio_back_cover"/>
  </joint>
  <link name="lio_back_cover">
    <inertial>
      <origin xyz="2.24196111270369E-06 -0.00408460946644196 -0.0510660065280277"/>
      <mass value="0.82454352978473"/>
      <inertia ixx="0.00151927417232363" ixy="-3.02654547820246E-07" ixz="-4.4543064624827E-08" iyy="0.00163894166884312" iyz="-2.0883019834409E-05" izz="0.00153211830480003"/>
    </inertial>
    <visual>
      <geometry>
        <mesh filename="package://p_grip_description/meshes/p_grip_2F/back_cover.STL"/>
      </geometry>
      <material name="white"/>
    </visual>
    <collision>
      <geometry>
        <mesh filename="package://p_grip_description/meshes/p_grip_2F/back_cover.STL"/>
      </geometry>
    </collision>
  </link>
  <!-- Main body of the gripper. -->
  <joint name="lio_p_grip_connector" type="fixed">
    <!-- <origin rpy="0 -1.57 3.14" xyz="-0.052 0 0.052"/> -->
    <origin rpy="0 -1.57 3.14" xyz="0 0 0.052"/> 
    <parent link="lio_gripper_interface_link"/>
    <child link="lio_gripper_link"/>
  </joint>
  <link name="lio_gripper_link">
    <inertial>
      <origin xyz="2.24196111270369E-06 -0.00408460946644196 -0.0510660065280277"/>
      <!-- <origin xyz="0 0 0"/> -->
      <mass value="0.82454352978473"/>
      <inertia ixx="0.00151927417232363" ixy="-3.02654547820246E-07" ixz="-4.4543064624827E-08" iyy="0.00163894166884312" iyz="-2.0883019834409E-05" izz="0.00153211830480003"/>
    </inertial>
    <visual>
      <geometry>
        <mesh filename="package://p_grip_description/meshes/p_grip_2F/p_grip.STL"/>
      </geometry>
      <origin xyz="0 0 -0.052"/>
      <material name="blue"/>
    </visual>
    <collision>
      <geometry>
        <mesh filename="package://p_grip_description/meshes/p_grip_2F/p_grip.STL"/>
      </geometry>
    </collision>
  </link>
  <!-- The left finger can be actuated via ROS. -->
  <joint name="lio_gripper_joint" type="revolute">
    <!-- <origin rpy="0 0 0" xyz="0.0645 0 0.052"/> -->
    <origin rpy="0 0 0" xyz="-0.1245 0 0"/>
    <parent link="lio_tcp_link"/>
    <child link="lio_left_finger"/>
    <limit effort="50" lower="0.0" upper="0.5235987755982988" velocity="1.0471975511965976"/>
    <axis xyz="0 0 1"/>
  </joint>
  <link name="lio_left_finger">
    <inertial>
      <!-- the inertia values are guessed-->
      <origin xyz="0 0 0"/>
      <mass value="0.1"/>
      <inertia ixx="0.0001" ixy="0.9" ixz="0.0" iyy="0.0001" iyz="0.0" izz="0.0001"/>
    </inertial>
    <visual>
      <origin rpy="0 0 0"/>
      <geometry>
        <mesh filename="package://p_grip_description/meshes/p_grip_2F/finger.STL"/>
      </geometry>
      <material name="black"/>
    </visual>
    <collision>
      <origin rpy="0 0 0"/>
      <geometry>
        <mesh filename="package://p_grip_description/meshes/p_grip_2F/finger.STL"/>
      </geometry>
    </collision>
  </link>
  <!-- The right finger simply mirrors the left one. -->
  <joint name="lio_passive_gripper_joint" type="revolute">
    <mimic joint="lio_gripper_joint" multiplier="-1" offset="0"/>
    <!-- <origin rpy="0 0 0" xyz="0.0645 0 0.052"/> -->
    <origin rpy="0 0 0" xyz="-0.1245 0 0"/>
    <parent link="lio_tcp_link"/>
    <child link="lio_right_finger"/>
    <limit effort="1000.0" lower="-0.5235987755982988" upper="0.0" velocity="170"/>
    <axis xyz="0 0 1"/>
  </joint>
  <link name="lio_right_finger">
    <inertial>
      <!-- the inertia values are guessed-->
      <origin xyz="0 0 0"/>
      <mass value="0.1"/>
      <inertia ixx="0.0001" ixy="0.9" ixz="0.0" iyy="0.0001" iyz="0.0" izz="0.0001"/>
    </inertial>
    <visual>
      <origin rpy="3.141592653589793 0 0"/>
      <geometry>
        <mesh filename="package://p_grip_description/meshes/p_grip_2F/finger.STL"/>
      </geometry>
      <material name="black"/>
    </visual>
    <collision>
      <origin rpy="3.141592653589793 0 0"/>
      <geometry>
        <mesh filename="package://p_grip_description/meshes/p_grip_2F/finger.STL"/>
      </geometry>
    </collision>
  </link>
  <!-- The tool center point is used for kinematics and path planning. -->
  <joint name="lio_tcp_joint" type="fixed">
    <!-- <origin rpy="0 0 0" xyz="0.189 0 0.052"/> -->
    <origin rpy="0 0 0" xyz="0.189 0 0"/>
    <parent link="lio_gripper_link"/>
    <child link="lio_tcp_link"/>
  </joint>
  <link name="lio_tcp_link">
    <inertial>
      <!-- the inertia values are guessed-->
      <origin xyz="0 0 0"/>
      <mass value="0.1"/>
      <inertia ixx="0.0001" ixy="0.9" ixz="0.0" iyy="0.0001" iyz="0.0" izz="0.0001"/>
    </inertial>
  </link>


  <joint name="lio_tis_cam_joint" type="fixed">
    <!-- <origin rpy="-1.5707963267948966 0.0 -1.5707963267948966" xyz="-0.095 0.0 0.053"/> -->
    <origin rpy="-1.5707963267948966 0.0 -1.5707963267948966" xyz="-0.095 0.0 0"/>
    <parent link="lio_tcp_link"/>
    <child link="tis_cam"/>
  </joint>
  <link name="tis_cam">
    <inertial>
      <!-- the inertia values are guessed but needed for gazebo -->
      <origin xyz="0 0 0"/>
      <mass value="0.001"/>
      <inertia ixx="0.0001" ixy="0.9" ixz="0.0" iyy="0.0001" iyz="0.0" izz="0.0001"/>
    </inertial>
  </link>
  <!-- we need this joint and link for the camera plugin in gazebo the x is taken for camera direction -->
  <joint name="lio_tis_cam_sim_plugin_joint" type="fixed">
    <origin rpy="0 -1.5707963267948966 0" xyz="0.0 0.0 0.0"/>
    <parent link="tis_cam"/>
    <child link="tis_cam_sim_plugin"/>
  </joint>
  <link name="tis_cam_sim_plugin">
    <inertial>
      <!-- the inertia values are guessed but needed for gazebo -->
      <origin xyz="0 0 0"/>
      <mass value="0.001"/>
      <inertia ixx="0.0001" ixy="0.9" ixz="0.0" iyy="0.0001" iyz="0.0" izz="0.0001"/>
    </inertial>
  </link>
</robot>

