<?xml version="1.0" ?>
<robot
  xmlns:xacro="http://www.ros.org/wiki/xacro">
  <xacro:macro
    name="p_grip"
    params="name parent version orientation">


  <xacro:property
    name="config_path"
    value="'$(find p_grip_description)/config/${version}/config.yaml'"/>
  <xacro:property
    name="parameters"
    value="${load_yaml(config_path)}"/>


  <!-- The parameter 'orientation' is either 'up' or 'side'. -->
  <xacro:macro name="connector_origin">
    <xacro:if value="${orientation == 'up'}">
      <origin xyz="${parameters['up_translation']}"
              rpy="${parameters['up_rotation']}"/>
    </xacro:if>
    <xacro:if value="${orientation == 'side'}">
      <origin xyz="0 0 0" rpy="0 0 0"/>
    </xacro:if>
  </xacro:macro>

  <!-- The back-cover protects the pins of the unconnected interface. -->
  <xacro:if value="${version == 'p_grip_2F'}">
    <joint name="${name}_back_cover_joint" type="fixed">
      <parent link="${parent}"/>
      <child link="${name}_back_cover"/>
    </joint>

    <link name="${name}_back_cover">
      <inertial>
        <origin xyz="2.24196111270369E-06 -0.00408460946644196 -0.0510660065280277"/>
        <mass
          value="0.82454352978473"/>
        <inertia
          ixx="0.00151927417232363"
          ixy="-3.02654547820246E-07"
          ixz="-4.4543064624827E-08"
          iyy="0.00163894166884312"
          iyz="-2.0883019834409E-05"
          izz="0.00153211830480003"/>
      </inertial>
      <visual>
        <geometry>
          <mesh
            filename="package://p_grip_description/meshes/${version}/back_cover.STL"/>
        </geometry>
        <material name="white"/>
      </visual>
      <collision>
        <geometry>
          <mesh
            filename="package://p_grip_description/meshes/${version}/back_cover.STL"/>
        </geometry>
      </collision>
    </link>
  </xacro:if>

  <!-- Main body of the gripper. -->
  <joint name="${name}_p_grip_connector" type="fixed">
    <xacro:connector_origin/>
    <parent link="${parent}"/>
    <child link="${name}_gripper_link"/>
  </joint>

  <link name="${name}_gripper_link">
    <inertial>
      <origin xyz="2.24196111270369E-06 -0.00408460946644196 -0.0510660065280277"/>
      <mass
        value="0.82454352978473"/>
      <inertia
        ixx="0.00151927417232363"
        ixy="-3.02654547820246E-07"
        ixz="-4.4543064624827E-08"
        iyy="0.00163894166884312"
        iyz="-2.0883019834409E-05"
        izz="0.00153211830480003"/>
    </inertial>
    <visual>
      <geometry>
        <mesh
          filename="package://p_grip_description/meshes/${version}/p_grip.STL"/>
      </geometry>
      <material name="blue"/>
    </visual>
    <collision>
      <geometry>
        <mesh
          filename="package://p_grip_description/meshes/${version}/p_grip.STL"/>
      </geometry>
    </collision>
  </link>

  <!-- The left finger can be actuated via ROS. -->
  <joint name="${name}_gripper_joint" type="revolute">
    <origin
      xyz="${parameters['left_finger_translation']}"
      rpy="${parameters['left_finger_rotation']}"/>
    <parent link="${name}_gripper_link"/>
    <child link="${name}_left_finger"/>
    <limit
      effort="${parameters['effort_limit']}"
      lower="${parameters['lower_angle_limit'] * pi/180}"
      upper="${parameters['upper_angle_limit'] * pi/180}"
      velocity="${parameters['velocity_limit'] * pi/180}"/>
    <axis xyz="0 0 1"/>
  </joint>

  <link name="${name}_left_finger">
    <inertial>
      <!-- the inertia values are guessed-->
      <origin xyz="0 0 0"/>
      <mass
        value="0.1"/>
      <inertia
        ixx="0.0001"
        ixy="0.9"
        ixz="0.0"
        iyy="0.0001"
        iyz="0.0"
        izz="0.0001"/>
    </inertial>
    <visual>
      <origin rpy="0 0 0"/>
      <geometry>
        <mesh filename="package://p_grip_description/meshes/${version}/finger.STL"/>
      </geometry>
    <material name="black"/>
    </visual>
    <collision>
        <origin rpy="0 0 0"/>
        <geometry>
          <mesh
            filename="package://p_grip_description/meshes/${version}/finger.STL"/>
        </geometry>
      </collision>
  </link>

  <!-- The tips are attached to their preceding fingers. -->
  <xacro:if value="${parameters['left_tip_translation'] != ''}">
    <joint name="${name}_left_finger_tip_joint" type="fixed">
      <axis xyz="0 0 1"/>
      <limit effort="1000.0" lower="0" upper="0.52" velocity="170"/>
      <origin xyz="${parameters['left_tip_translation']}"/>
      <parent link="${name}_left_finger"/>
      <child link="${name}_left_finger_tip"/>
    </joint>

    <link name="${name}_left_finger_tip">
    <inertial>
      <!-- the inertia values are guessed-->
      <origin xyz="0 0 0"/>
      <mass
        value="0.01"/>
      <inertia
        ixx="0.0001"
        ixy="0.9"
        ixz="0.0"
        iyy="0.0001"
        iyz="0.0"
        izz="0.0001"/>
    </inertial>
      <visual>
        <origin rpy="0 0 0"/>
        <geometry>
          <mesh
            filename="package://p_grip_description/meshes/${version}/finger_tip.STL"/>
        </geometry>
        <material name="white"/>
      </visual>
      <collision>
        <origin rpy="0 0 0"/>
        <geometry>
          <mesh
            filename="package://p_grip_description/meshes/${version}/finger_tip.STL"/>
        </geometry>
      </collision>
    </link>
  </xacro:if>

  <!-- The right finger simply mirrors the left one. -->
  <joint name="${name}_passive_gripper_joint" type="revolute">
    <mimic joint="${name}_gripper_joint" multiplier="-1" offset="0"/>
    <origin
            xyz="${parameters['right_finger_translation']}"
            rpy="${parameters['right_finger_rotation']}"/>
    <parent link="${name}_gripper_link"/>
    <child link="${name}_right_finger"/>
    <limit effort="1000.0" lower="-${parameters['upper_angle_limit'] * pi/180}" upper="${parameters['lower_angle_limit'] * pi/180}" velocity="170"/>
    <axis xyz="0 0 1"/>
  </joint>

  <link name="${name}_right_finger">
    <inertial>
      <!-- the inertia values are guessed-->
      <origin xyz="0 0 0"/>
      <mass
        value="0.1"/>
      <inertia
        ixx="0.0001"
        ixy="0.9"
        ixz="0.0"
        iyy="0.0001"
        iyz="0.0"
        izz="0.0001"/>
    </inertial>
    <visual>
      <origin rpy="${pi} 0 0"/>
      <geometry>
        <mesh filename="package://p_grip_description/meshes/${version}/finger.STL"/>
      </geometry>
      <material name="black"/>
    </visual>
    <collision>
      <origin rpy="${pi} 0 0"/>
      <geometry>
        <mesh
          filename="package://p_grip_description/meshes/${version}/finger.STL"/>
      </geometry>
    </collision>
  </link>

  <!-- Right finger tip.-->
  <xacro:if value="${parameters['right_tip_translation'] != ''}">
    <joint name="${name}_right_finger_tip_joint" type="fixed">
      <origin xyz="${parameters['right_tip_translation']}"/>
      <parent link="${name}_right_finger"/>
      <child link="${name}_right_finger_tip"/>
      <limit effort="1000.0" lower="0" upper="0.52" velocity="170"/>
      <axis xyz="0 0 1"/>
    </joint>

    <link name="${name}_right_finger_tip">
    <inertial>
      <!-- the inertia values are guessed-->
      <origin xyz="0 0 0"/>
      <mass
        value="0.1"/>
      <inertia
        ixx="0.0001"
        ixy="0.9"
        ixz="0.0"
        iyy="0.0001"
        iyz="0.0"
        izz="0.0001"/>
    </inertial>
      <visual>
        <origin rpy="${pi} 0 0"/>
        <geometry>
          <mesh
            filename="package://p_grip_description/meshes/${version}/finger_tip.STL"/>
        </geometry>
        <material name="white"/>
      </visual>
      <collision>
        <origin rpy="${pi} 0 0"/>
        <geometry>
          <mesh
            filename="package://p_grip_description/meshes/${version}/finger_tip.STL"/>
        </geometry>
      </collision>
    </link>
  </xacro:if>

  <!-- The tool center point is used for kinematics and path planning. -->
  <joint name="${name}_tcp_joint" type="fixed">
    <origin
      xyz="${parameters['tcp_translation']}"
      rpy="${parameters['tcp_rotation']}"/>
    <parent link="${name}_gripper_link"/>
    <child link="${name}_tcp_link"/>
  </joint>

  <link name="${name}_tcp_link" >
    <inertial>
      <!-- the inertia values are guessed-->
      <origin xyz="0 0 0"/>
      <mass
        value="0.1"/>
      <inertia
        ixx="0.0001"
        ixy="0.9"
        ixz="0.0"
        iyy="0.0001"
        iyz="0.0"
        izz="0.0001"/>
    </inertial>
  </link>

  </xacro:macro>
</robot>
