<?xml version="1.0" ?>
<!-- =================================================================================== -->
<!-- |    This document was autogenerated by xacro from p_rob.urdf.xacro               | -->
<!-- |    EDITING THIS FILE BY HAND IS NOT RECOMMENDED                                 | -->
<!-- =================================================================================== -->
<robot name="p_rob" xmlns:xacro="http://www.ros.org/wiki/xacro">
  <material name="blue">
    <color rgba="0.12549019607843137 0.2784313725490196 0.43529411764705883 1"/>
  </material>
  <material name="black">
    <color rgba="0 0 0 1"/>
  </material>
  <material name="white">
    <color rgba="1 1 1 1"/>
  </material>
  <link name="base_link">
    <inertial>
      <origin rpy="0 0 0" xyz="8.71294630254049E-05 0.508451295685675 -0.00113740271757783"/>
      <mass value="31.8818528911811"/>
      <inertia ixx="4.65436888537887" ixy="-0.0338576061896482" ixz="3.29763186167614E-06" iyy="0.165544422845209" iyz="-0.00333281637307909" izz="4.60911765357231"/>
    </inertial>
    <visual>
      <geometry>
        <mesh filename="package://p_rob_description/meshes/p_base.STL"/>
      </geometry>
      <material name="white"/>
    </visual>
    <collision>
      <geometry>
        <mesh filename="package://p_rob_description/meshes/p_base.STL"/>
      </geometry>
    </collision>
  </link>
  <joint name="p_rob_joint1" type="revolute">
    <origin xyz="0 0 0.212"/>
    <parent link="base_link"/>
    <child link="p_rob_link12"/>
    <limit effort="1.09" lower="-2.96705972839" upper="2.96705972839" velocity="0.829031394697"/>
    <axis xyz="0 0 1"/>
  </joint>
  <link name="p_rob_link12">
    <inertial>
      <origin rpy="0 0 0" xyz="8.71294630254049E-05 0.277951295685675 -0.00113740271757783"/>
      <mass value="3.652"/>
      <inertia ixx="0.06656" ixy="1e-05" ixz="1e-05" iyy="0.0661" iyz="0.00952" izz="0.0076"/>
    </inertial>
    <visual>
      <geometry>
        <mesh filename="package://p_arm_description/meshes/p_rob_2R/link12.STL"/>
      </geometry>
      <material name="blue"/>
    </visual>
    <collision>
      <geometry>
        <mesh filename="package://p_arm_description/meshes/p_rob_2R/link12.STL"/>
      </geometry>
    </collision>
  </link>
  <joint name="p_rob_joint2" type="revolute">
    <origin xyz="0 0 0.1505"/>
    <parent link="p_rob_link12"/>
    <child link="p_rob_link23"/>
    <limit effort="1.09" lower="-1.91986217719" upper="1.91986217719" velocity="0.829031394697"/>
    <axis xyz="0 1 0"/>
  </joint>
  <link name="p_rob_link23">
    <inertial>
      <origin xyz="8.71294630254052E-05 0.000951295697065868 -0.00113740271757783"/>
      <mass value="3.52"/>
      <inertia ixx="0.18406" ixy="2e-05" ixz="-8e-05" iyy="0.18142" iyz="0.01932" izz="0.00841"/>
    </inertial>
    <visual>
      <geometry>
        <mesh filename="package://p_arm_description/meshes/p_rob_2R/link23.STL"/>
      </geometry>
      <material name="white"/>
    </visual>
    <collision>
      <geometry>
        <mesh filename="package://p_arm_description/meshes/p_rob_2R/link23.STL"/>
      </geometry>
    </collision>
  </link>
  <joint name="p_rob_joint3" type="revolute">
    <origin xyz="0 0 0.29"/>
    <parent link="p_rob_link23"/>
    <child link="p_rob_link34"/>
    <limit effort="1.09" lower="-2.00712863979" upper="2.00712863979" velocity="0.829031394697"/>
    <axis xyz="0 1 0"/>
  </joint>
  <link name="p_rob_link34">
    <inertial>
      <origin rpy="0 0 0" xyz="8.71294630254052E-05 -0.313548704302934 -0.00113740271757783"/>
      <mass value="1.626"/>
      <inertia ixx="0.02372" ixy="-2e-05" ixz="4e-05" iyy="0.02243" iyz="0.00024" izz="0.0343"/>
    </inertial>
    <visual>
      <geometry>
        <mesh filename="package://p_arm_description/meshes/p_rob_2R/link34.STL"/>
      </geometry>
      <material name="blue"/>
    </visual>
    <collision>
      <geometry>
        <mesh filename="package://p_arm_description/meshes/p_rob_2R/link34.STL"/>
      </geometry>
    </collision>
  </link>
  <joint name="p_rob_joint4" type="revolute">
    <origin xyz="0 0 0.1645"/>
    <parent link="p_rob_link34"/>
    <child link="p_rob_link45"/>
    <limit effort="0.3275" lower="-2.96705972839" upper="2.96705972839" velocity="0.829031394697"/>
    <axis xyz="0 0 1"/>
  </joint>
  <link name="p_rob_link45">
    <inertial>
      <origin rpy="0 0 0" xyz="8.71294630254052E-05 -0.313548704302934 -0.00113740271757783"/>
      <mass value="1.516"/>
      <inertia ixx="0.02488" ixy="2e-05" ixz="3e-05" iyy="0.02409" iyz="0.00398" izz="0.00272"/>
    </inertial>
    <visual>
      <geometry>
        <mesh filename="package://p_arm_description/meshes/p_rob_2R/link45.STL"/>
      </geometry>
      <material name="white"/>
    </visual>
    <collision>
      <geometry>
        <mesh filename="package://p_arm_description/meshes/p_rob_2R/link45.STL"/>
      </geometry>
    </collision>
  </link>
  <joint name="p_rob_joint5" type="revolute">
    <origin xyz="0 0 0.1455"/>
    <parent link="p_rob_link45"/>
    <child link="p_rob_link56"/>
    <limit effort="0.3275" lower="-2.00712863979" upper="2.00712863979" velocity="0.829031394697"/>
    <axis xyz="0 1 0"/>
  </joint>
  <link name="p_rob_link56">
    <inertial>
      <origin xyz="-8.71294630254049E-05 -0.588048704302934 0.00113740271757783"/>
      <mass value="1.417"/>
      <inertia ixx="0.01351" ixy="-2e-05" ixz="-3e-05" iyy="0.01261" iyz="-0.00012" izz="0.00274"/>
    </inertial>
    <visual>
      <geometry>
        <mesh filename="package://p_arm_description/meshes/p_rob_2R/link56.STL"/>
      </geometry>
      <material name="blue"/>
    </visual>
    <collision>
      <geometry>
        <mesh filename="package://p_arm_description/meshes/p_rob_2R/link56.STL"/>
      </geometry>
    </collision>
  </link>
  <joint name="p_rob_joint6" type="revolute">
    <origin xyz="0 0 0.129"/>
    <parent link="p_rob_link56"/>
    <child link="p_rob_link6G"/>
    <limit effort="0.179324" lower="-2.96705972839" upper="2.96705972839" velocity="1.65806278939"/>
    <axis xyz="0 0 1"/>
  </joint>
  <link name="p_rob_link6G">
    <inertial>
      <origin xyz="-0.00113740271757783 0.588048704302934 8.7129463025477E-05"/>
      <mass value="0.435"/>
      <inertia ixx="0.00079" ixy="0.0" ixz="0.0" iyy="0.00086" iyz="-1e-05" izz="0.00084"/>
    </inertial>
    <visual>
      <geometry>
        <mesh filename="package://p_arm_description/meshes/p_rob_2R/link6G.STL"/>
      </geometry>
      <material name="white"/>
    </visual>
    <collision>
      <geometry>
        <mesh filename="package://p_arm_description/meshes/p_rob_2R/link6G.STL"/>
      </geometry>
    </collision>
  </link>
  <joint name="p_rob_gripper_interface_joint" type="fixed">
    <origin xyz="0 0 0.046"/>
    <parent link="p_rob_link6G"/>
    <child link="p_rob_gripper_interface_link"/>
  </joint>
  <link name="p_rob_gripper_interface_link"/>
  <joint name="p_rob_back_cover_joint" type="fixed">
    <parent link="p_rob_gripper_interface_link"/>
    <child link="p_rob_back_cover"/>
  </joint>
  <link name="p_rob_back_cover">
    <inertial>
      <origin xyz="2.24196111270369E-06 -0.00408460946644196 -0.0510660065280277"/>
      <mass value="0.82454352978473"/>
      <inertia ixx="0.00151927417232363" ixy="-3.02654547820246E-07" ixz="-4.4543064624827E-08" iyy="0.00163894166884312" iyz="-2.0883019834409E-05" izz="0.00153211830480003"/>
    </inertial>
    <visual>
      <geometry>
        <mesh filename="package://p_grip_description/meshes/p_grip_2F/back_cover.STL"/>
      </geometry>
      <material name="white"/>
    </visual>
    <collision>
      <geometry>
        <mesh filename="package://p_grip_description/meshes/p_grip_2F/back_cover.STL"/>
      </geometry>
    </collision>
  </link>
  <!-- Main body of the gripper. -->
  <joint name="p_rob_p_grip_connector" type="fixed">
    <origin rpy="0 0 0" xyz="0 0 0"/>
    <parent link="p_rob_gripper_interface_link"/>
    <child link="p_rob_gripper_link"/>
  </joint>
  <link name="p_rob_gripper_link">
    <inertial>
      <origin xyz="2.24196111270369E-06 -0.00408460946644196 -0.0510660065280277"/>
      <mass value="0.82454352978473"/>
      <inertia ixx="0.00151927417232363" ixy="-3.02654547820246E-07" ixz="-4.4543064624827E-08" iyy="0.00163894166884312" iyz="-2.0883019834409E-05" izz="0.00153211830480003"/>
    </inertial>
    <visual>
      <geometry>
        <mesh filename="package://p_grip_description/meshes/p_grip_2F/p_grip.STL"/>
      </geometry>
      <material name="blue"/>
    </visual>
    <collision>
      <geometry>
        <mesh filename="package://p_grip_description/meshes/p_grip_2F/p_grip.STL"/>
      </geometry>
    </collision>
  </link>
  <!-- The left finger can be actuated via ROS. -->
  <joint name="p_rob_gripper_joint" type="revolute">
    <origin rpy="0 0 0" xyz="0.0645 0 0.052"/>
    <parent link="p_rob_gripper_link"/>
    <child link="p_rob_left_finger"/>
    <limit effort="0.11997" lower="0.0" upper="0.523598775598" velocity="1.0471975512"/>
    <axis xyz="0 0 1"/>
  </joint>
  <link name="p_rob_left_finger">
    <visual>
      <origin rpy="0 0 0"/>
      <geometry>
        <mesh filename="package://p_grip_description/meshes/p_grip_2F/finger.STL"/>
      </geometry>
      <material name="black"/>
    </visual>
    <collision>
      <origin rpy="0 0 0"/>
      <geometry>
        <mesh filename="package://p_grip_description/meshes/p_grip_2F/finger.STL"/>
      </geometry>
    </collision>
  </link>
  <!-- The right finger simply mirrors the left one. -->
  <joint name="p_rob_passive_gripper_joint" type="revolute">
    <mimic joint="p_rob_gripper_joint" multiplier="-1" offset="0"/>
    <origin rpy="0 0 0" xyz="0.0645 0 0.052"/>
    <parent link="p_rob_gripper_link"/>
    <child link="p_rob_right_finger"/>
    <limit effort="1000.0" lower="0" upper="0.52" velocity="170"/>
    <axis xyz="0 0 1"/>
  </joint>
  <link name="p_rob_right_finger">
    <visual>
      <origin rpy="3.14159265359 0 0"/>
      <geometry>
        <mesh filename="package://p_grip_description/meshes/p_grip_2F/finger.STL"/>
      </geometry>
      <material name="black"/>
    </visual>
    <collision>
      <origin rpy="3.14159265359 0 0"/>
      <geometry>
        <mesh filename="package://p_grip_description/meshes/p_grip_2F/finger.STL"/>
      </geometry>
    </collision>
  </link>
  <!-- The tool center point is used for kinematics and path planning. -->
  <joint name="p_rob_tcp_joint" type="fixed">
    <origin rpy="0 0 0" xyz="0.189 0 0.052"/>
    <parent link="p_rob_gripper_link"/>
    <child link="p_rob_tcp_link"/>
  </joint>
  <link name="p_rob_tcp_link"/>
</robot>

